<?xml version="1.0" encoding="utf-8"?>
<!-- =================================================================================== -->
<!-- |    This document was autogenerated by xacro from dogbot.xacro                   | -->
<!-- |    EDITING THIS FILE BY HAND IS NOT RECOMMENDED                                 | -->
<!-- =================================================================================== -->
<robot name="dogbot">

  <material name="blue">
    <color rgba="0 0 0.8 1"/>
  </material>
  <material name="black">
    <color rgba="0 0 0 1"/>
  </material>
  <material name="white">
    <color rgba="1 1 1 1"/>
  </material>
  <material name="dogbotred">
    <color rgba="1 0 0 1"/>
  </material>
  <material name="dogbotgray">
    <color rgba="0.7 0.7 0.7 1"/>
  </material>
  <!-- start the robot links -->

  <link name="base">
  </link>

  <link name="FL_hip">
  </link>
  <link name="FR_hip">
  </link>
  <link name="RL_hip">
  </link>
  <link name="RR_hip">
  </link>




  <joint name="FL_hip_joint" type="fixed">
    <axis rpy="0 0 0" xyz="0 0 0"/>
    <origin rpy="0 1.57 0" xyz="0.278 0.088 0"/>
    <parent link="base"/>
    <child link="FL_hip"/>
  </joint>
  <joint name="FR_hip_joint" type="fixed">
    <axis rpy="0 0 0" xyz="0 0 0"/>
    <origin rpy="0 1.57 0" xyz="0.278 -0.088 0"/>
    <parent link="base"/>
    <child link="FR_hip"/>
  </joint>
  <joint name="RL_hip_joint" type="fixed">
    <axis rpy="0 0 0" xyz="0 0 0"/>
    <origin rpy="0 1.57 0" xyz="-0.278 0.088 0"/>
    <parent link="base"/>
    <child link="RL_hip"/>
  </joint>
  <joint name="RR_hip_joint" type="fixed">
    <axis rpy="0 0 0" xyz="0 0 0"/>
    <origin rpy="0 1.57 0" xyz="-0.278 -0.088 0"/>
    <parent link="base"/>
    <child link="RR_hip"/>
  </joint>

  <joint name="trunk_joint" type="fixed">
    <axis rpy="0 0 0" xyz="0 0 0"/>
    <origin rpy="0 0 3.14" xyz="0 0 0"/>
    <parent link="base"/>
    <child link="trunk"/>
  </joint>
  <link name="trunk">
  </link>

  <gazebo>
        <plugin name="p3d_base_controller" filename="libgazebo_ros_p3d.so">
        <alwaysOn>true</alwaysOn>
        <updateRate>5000.0</updateRate>
        <bodyName>base</bodyName>
        <topicName>odom</topicName>
        <gaussianNoise>0.0001</gaussianNoise>
        <frameName>world</frameName>
        <xyzOffsets>0 0 0</xyzOffsets>
        <rpyOffsets>0 0 0</rpyOffsets>
        </plugin>
  </gazebo> 


  <material name="camera_aluminum">
    <color rgba="0.5 0.5 0.5 1"/>
  </material>

  <joint name="camera_joint" type="fixed">
    <origin rpy="0 0.1919 -3.14" xyz="-0.4115 0 -0.032"/>
    <parent link="trunk"/>
    <child link="camera_bottom_screw_frame"/>
  </joint>
  <link name="camera_bottom_screw_frame"/>
  <joint name="camera_link_joint" type="fixed">
    <origin rpy="0 0 0" xyz="0 0.0175 0.0125"/>
    <parent link="camera_bottom_screw_frame"/>
    <child link="camera_link"/>
  </joint>
  <link name="camera_link">
    <visual>
      <origin rpy="1.57079632679 0 1.57079632679" xyz="0.0149 -0.0175 0"/>
      <geometry>
        <!-- <box size="0.09 0.025 0.02505"/> -->
        <mesh filename="package://realsense2_description/meshes/d435.dae"/>
        <!--<mesh filename="package://realsense2_description/meshes/d435/d435.dae" />-->
      </geometry>
      <material name="camera_aluminum"/>
    </visual>
    <collision>
      <origin rpy="0 0 0" xyz="0 -0.0175 0"/>
      <geometry>
        <box size="0.02505 0.09 0.025"/>
      </geometry>
    </collision>
  </link>
  <joint name="camera_depth_joint" type="fixed">
    <origin rpy="0 0 0" xyz="0 0 0"/>
    <parent link="camera_link"/>
    <child link="camera_depth_frame"/>
  </joint>
  <link name="camera_depth_frame"/>
  <joint name="camera_depth_optical_joint" type="fixed">
    <origin rpy="-1.57079632679 0 -1.57079632679" xyz="0 0 0"/>
    <parent link="camera_depth_frame"/>
    <child link="camera_depth_optical_frame"/>
  </joint>
  <link name="camera_depth_optical_frame"/>
  <joint name="camera_left_ir_joint" type="fixed">
    <origin rpy="0 0 0" xyz="0 0.0 0"/>
    <parent link="camera_depth_frame"/>
    <child link="camera_left_ir_frame"/>
  </joint>
  <link name="camera_left_ir_frame"/>
  <joint name="camera_left_ir_optical_joint" type="fixed">
    <origin rpy="-1.57079632679 0 -1.57079632679" xyz="0 0 0"/>
    <parent link="camera_left_ir_frame"/>
    <child link="camera_left_ir_optical_frame"/>
  </joint>
  <link name="camera_left_ir_optical_frame"/>
  <joint name="camera_right_ir_joint" type="fixed">
    <origin rpy="0 0 0" xyz="0 -0.05 0"/>
    <parent link="camera_depth_frame"/>
    <child link="camera_right_ir_frame"/>
  </joint>
  <link name="camera_right_ir_frame"/>
  <joint name="camera_right_ir_optical_joint" type="fixed">
    <origin rpy="-1.57079632679 0 -1.57079632679" xyz="0 0 0"/>
    <parent link="camera_right_ir_frame"/>
    <child link="camera_right_ir_optical_frame"/>
  </joint>
  <link name="camera_right_ir_optical_frame"/>
  <joint name="camera_color_joint" type="fixed">
    <origin rpy="0 0 0" xyz="0 0.015 0"/>
    <parent link="camera_depth_frame"/>
    <child link="camera_color_frame"/>
  </joint>
  <link name="camera_color_frame"/>
  <joint name="camera_color_optical_joint" type="fixed">
    <origin rpy="-1.57079632679 0 -1.57079632679" xyz="0 0 0"/>
    <parent link="camera_color_frame"/>
    <child link="camera_color_optical_frame"/>
  </joint>
  <link name="camera_color_optical_frame"/>
  <gazebo reference="camera_link">
    <self_collide>0</self_collide>
    <enable_wind>0</enable_wind>
    <kinematic>0</kinematic>
    <gravity>1</gravity>
    <!--<mu>1</mu>-->
    <mu2>1</mu2>
    <fdir1>0 0 0</fdir1>
    <!--<slip1>0</slip1>
      <slip2>0</slip2>-->
    <kp>1e+13</kp>
    <kd>1</kd>
    <!--<max_vel>0.01</max_vel>
      <min_depth>0</min_depth>-->
    <sensor name="cameracolor" type="camera">
      <camera name="camera">
        <horizontal_fov>1.5</horizontal_fov>
        <image>
          <width>1280</width>
          <height>720</height>
          <format>RGB_INT8</format>
        </image>
        <clip>
          <near>0.1</near>
          <far>100</far>
        </clip>
        <noise>
          <type>gaussian</type>
          <mean>0.0</mean>
          <stddev>0.007</stddev>
        </noise>
      </camera>
      <always_on>1</always_on>
      <update_rate>30</update_rate>
      <visualize>0</visualize>
    </sensor>
    <sensor name="cameraired1" type="camera">
      <camera name="camera">
        <horizontal_fov>1.4870205227</horizontal_fov>
        <image>
          <width>1280</width>
          <height>720</height>
          <format>L_INT8</format>
        </image>
        <clip>
          <near>0.1</near>
          <far>100</far>
        </clip>
        <noise>
          <type>gaussian</type>
          <mean>0.0</mean>
          <stddev>0.05</stddev>
        </noise>
      </camera>
      <always_on>0</always_on>
      <update_rate>90</update_rate>
      <visualize>0</visualize>
    </sensor>
    <sensor name="cameraired2" type="camera">
      <camera name="camera">
        <horizontal_fov>1.4870205227</horizontal_fov>
        <image>
          <width>1280</width>
          <height>720</height>
          <format>L_INT8</format>
        </image>
        <clip>
          <near>0.1</near>
          <far>100</far>
        </clip>
        <noise>
          <type>gaussian</type>
          <mean>0.0</mean>
          <stddev>0.05</stddev>
        </noise>
      </camera>
      <always_on>0</always_on>
      <update_rate>90</update_rate>
      <visualize>0</visualize>
    </sensor>
    <sensor name="cameradepth" type="depth">
      <camera name="camera">
        <horizontal_fov>1.5</horizontal_fov>
        <image>
          <width>1280</width>
          <height>720</height>
        </image>
        <clip>
          <near>0.1</near>
          <far>100</far>
        </clip>
        <noise>
          <type>gaussian</type>
          <mean>0.0</mean>
          <stddev>0.100</stddev>
        </noise>
      </camera>
      <always_on>1</always_on>
      <update_rate>90</update_rate>
      <visualize>0</visualize>
    </sensor>
  </gazebo>
  <gazebo>
    <plugin filename="librealsense_gazebo_plugin.so" name="camera">
      <prefix>camera</prefix>
      <depthUpdateRate>30.0</depthUpdateRate>
      <colorUpdateRate>30.0</colorUpdateRate>
      <infraredUpdateRate>30.0</infraredUpdateRate>
      <depthTopicName>depth/image_raw</depthTopicName>
      <depthCameraInfoTopicName>depth/camera_info</depthCameraInfoTopicName>
      <colorTopicName>color/image_raw</colorTopicName>
      <colorCameraInfoTopicName>color/camera_info</colorCameraInfoTopicName>
      <infrared1TopicName>infra1/image_raw</infrared1TopicName>
      <infrared1CameraInfoTopicName>infra1/camera_info</infrared1CameraInfoTopicName>
      <infrared2TopicName>infra2/image_raw</infrared2TopicName>
      <infrared2CameraInfoTopicName>infra2/camera_info</infrared2CameraInfoTopicName>
      <colorOpticalframeName>camera_depth_optical_frame</colorOpticalframeName>
      <depthOpticalframeName>camera_depth_optical_frame</depthOpticalframeName>
      <infrared1OpticalframeName>camera_left_ir_optical_frame</infrared1OpticalframeName>
      <infrared2OpticalframeName>camera_right_ir_optical_frame</infrared2OpticalframeName>
      <rangeMinDepth>0.28</rangeMinDepth>
      <rangeMaxDepth>10.0</rangeMaxDepth>
    </plugin>
  </gazebo>
















  <link name="body">
    <visual>
      <origin rpy="-1.57079632679 0 0" xyz="0 0 0"/>
      <geometry>
        <mesh filename="package://dogbot_description/meshes/body.dae" scale="1.0 1.0 1.0"/>
      </geometry>
    </visual>
    <collision>
      <origin rpy="0 0 0" xyz="0 0 0"/>
      <geometry>
        <box size="0.177 0.433 0.105"/>
      </geometry>
    </collision>
    <collision>
      <origin rpy="1.57079632679 0 0" xyz="0.0885 0 0"/>
      <geometry>
        <cylinder length="0.433" radius="0.0525"/>
      </geometry>
    </collision>
    <collision>
      <origin rpy="1.57079632679 0 0" xyz="-0.0885 0 0"/>
      <geometry>
        <cylinder length="0.433" radius="0.0525"/>
      </geometry>
    </collision>
    <collision>
      <origin rpy="0 0 0" xyz="0 0.2825 0"/>
      <geometry>
        <box size="0.035 0.132 0.105"/>
      </geometry>
    </collision>
    <collision>
      <origin rpy="0 0 0" xyz="0 -0.2825 0"/>
      <geometry>
        <box size="0.035 0.132 0.105"/>
      </geometry>
    </collision>
    <collision>
      <origin rpy="0 0 0" xyz="0 0.3975 0"/>
      <geometry>
        <box size="0.177 0.08 0.105"/>
      </geometry>
    </collision>
    <collision>
      <origin rpy="1.57079632679 0 0" xyz="0.0885 0.3975 0"/>
      <geometry>
        <cylinder length="0.08" radius="0.0525"/>
      </geometry>
    </collision>
    <collision>
      <origin rpy="1.57079632679 0 0" xyz="-0.0885 0.3975 0"/>
      <geometry>
        <cylinder length="0.08" radius="0.0525"/>
      </geometry>
    </collision>
    <collision>
      <origin rpy="0 0 0" xyz="0 -0.3975 0"/>
      <geometry>
        <box size="0.177 0.08 0.105"/>
      </geometry>
    </collision>
    <collision>
      <origin rpy="1.57079632679 0 0" xyz="0.0885 -0.3975 0"/>
      <geometry>
        <cylinder length="0.08" radius="0.0525"/>
      </geometry>
    </collision>
    <collision>
      <origin rpy="1.57079632679 0 0" xyz="-0.0885 -0.3975 0"/>
      <geometry>
        <cylinder length="0.08" radius="0.0525"/>
      </geometry>
    </collision>
    <inertial>
      <mass value="9.3"/>
      <origin rpy="0 0 0" xyz="0 0 0"/>
      <inertia ixx="0.41" ixy="0" ixz="0" iyy="0.091" iyz="0" izz="0.482"/>
    </inertial>
  </link>
  <joint name="base_joint" type="fixed">
    <axis rpy="0 0 0" xyz="0 0 0"/>
    <origin rpy="0 0 -1.57" xyz="0 0 0"/>
    <parent link="trunk"/>
    <child link="body"/>
  </joint>
  <link name="bodytext">
    <visual>
      <origin rpy="-1.57079632679 0 0" xyz="0 0 0"/>
      <geometry>
        <mesh filename="package://dogbot_description/meshes/bodyTEXT.dae" scale="1.0 1.0 1.0"/>
      </geometry>
    </visual>
    <inertial>
      <mass value="0.001"/>
      <origin rpy="0 0 0" xyz="0 0 0"/>
      <inertia ixx="1.66666666667e-10" ixy="0.0" ixz="0.0" iyy="1.66666666667e-10" iyz="0.0" izz="1.66666666667e-10"/>
    </inertial>
  </link>
  <joint name="bodytext_joint" type="fixed">
    <parent link="body"/>
    <child link="bodytext"/>
  </joint>
  <gazebo reference="body">
    <mu1 value="200.0"/>
    <mu2 value="100.0"/>
    <kp value="1000000"/>
    <kd value="1.0"/>
  </gazebo>
  <link name="back_left_hip">
    <visual>
      <origin rpy="-1.57079632679 -3.14159265359 0" xyz="0 0 0"/>
      <geometry>
        <mesh filename="package://dogbot_description/meshes/hip.dae" scale="1.0 1.0 1.0"/>
      </geometry>
    </visual>
    <collision>
      <origin rpy="0 1.57079632679 0" xyz="-0.02 0 0"/>
      <geometry>
        <cylinder length="0.08" radius="0.0525"/>
      </geometry>
    </collision>
    <inertial>
      <mass value="0.836"/>
      <origin rpy="0 0 0" xyz="-0.0074 0 0"/>
      <inertia ixx="0.00213" ixy="0" ixz="0" iyy="0.00147" iyz="0" izz="0.00172"/>
    </inertial>
  </link>
  <!-- roll joint connects the hip to the body -->
  <joint name="back_left_roll_joint" type="revolute">
    <axis rpy="0 0 0" xyz="0 -1 0"/>
    <parent link="body"/>
    <child link="back_left_hip"/>
    <origin rpy="0 0 0" xyz="-0.088 -0.2875 0"/>
    <limit effort="60" lower="-1.7453" upper="1.7453" velocity="6.0"/>
  </joint>
  <link name="back_left_upperleg">
    <visual>
      <origin rpy="-1.57079632679 0 -3.14159265359" xyz="0 0 0"/>
      <geometry>
        <mesh filename="package://dogbot_description/meshes/LegUpper_withCover.dae" scale="1.0 1.0 1.0"/>
      </geometry>
    </visual>
    <collision>
      <origin rpy="0 1.57079632679 0" xyz="-0.03 0 0"/>
      <geometry>
        <cylinder length="0.13" radius="0.0525"/>
      </geometry>
    </collision>
    <collision>
      <origin rpy="0 0 0" xyz="0 0 -0.135"/>
      <geometry>
        <cylinder length="0.27" radius="0.033"/>
      </geometry>
    </collision>
    <collision>
      <origin rpy="0 0 0" xyz="0 0 -0.135"/>
      <geometry>
        <box size="0.025 0.084 0.27"/>
      </geometry>
    </collision>
    <collision>
      <origin rpy="0 0 0" xyz="-0.046 0 -0.126"/>
      <geometry>
        <box size="0.026 0.074 0.138"/>
      </geometry>
    </collision>
    <collision>
      <origin rpy="0 1.57079632679 0" xyz="-0.03 0 -0.315"/>
      <geometry>
        <cylinder length="0.018" radius="0.017"/>
      </geometry>
    </collision>
    <collision>
      <origin rpy="0 1.57079632679 0" xyz="0.036 0 -0.315"/>
      <geometry>
        <cylinder length="0.013" radius="0.017"/>
      </geometry>
    </collision>
    <inertial>
      <mass value="1.851"/>
      <origin rpy="0 0 0" xyz="-0.0418 0 -0.0517"/>
      <inertia ixx="0.0238" ixy="0" ixz="0" iyy="0.0252" iyz="0" izz="0.0044"/>
    </inertial>
  </link>
  <!-- pitch joint connects hip to upper leg -->
  <joint name="back_left_pitch_joint" type="revolute">
    <axis rpy="0 0 0" xyz="-1 0 0"/>
    <parent link="back_left_hip"/>
    <child link="back_left_upperleg"/>
    <origin rpy="0 0 0" xyz="-0.09875 0 0"/>
    <limit effort="60" lower="-1.57079632679" upper="3.14159265359" velocity="6.0"/>
  </joint>
  <link name="back_left_lowerleg">
    <visual>
      <origin rpy="-1.57079632679 0 0" xyz="0 0 0"/>
      <geometry>
        <mesh filename="package://dogbot_description/meshes/LegLower_nofoot.dae" scale="1.0 1.0 1.0"/>
      </geometry>
    </visual>
    <collision>
      <origin rpy="0 1.57079632679 0" xyz="0 0 0"/>
      <geometry>
        <cylinder length="0.033" radius="0.042"/>
      </geometry>
    </collision>
    <collision>
      <origin rpy="0 0 0" xyz="0.024 -0.0375 -0.0055"/>
      <geometry>
        <box size="0.02 0.017 0.065"/>
      </geometry>
    </collision>
    <collision>
      <origin rpy="0 0 0" xyz="-0.024 -0.0375 -0.0055"/>
      <geometry>
        <box size="0.02 0.017 0.065"/>
      </geometry>
    </collision>
    <collision>
      <origin rpy="0 0.04996 0" xyz="0.01575 -0.0375 -0.145"/>
      <geometry>
        <cylinder length="0.29" radius="0.006"/>
      </geometry>
    </collision>
    <collision>
      <origin rpy="0 -0.04996 0" xyz="-0.01575 -0.0375 -0.145"/>
      <geometry>
        <cylinder length="0.29" radius="0.006"/>
      </geometry>
    </collision>
    <inertial>
      <mass value="0.302"/>
      <origin rpy="0 0 0" xyz="0 -0.029 -0.1439"/>
      <inertia ixx="0.00527" ixy="0" ixz="0" iyy="0.00509" iyz="0" izz="0.0008"/>
    </inertial>
  </link>
  <gazebo reference="back_left_lowerleg">
    <mu1 value="2000.0"/>
    <mu2 value="1000.0"/>
    <kp value="1000000"/>
    <kd value="1.0"/>
    <selfCollide value="true"/>
  </gazebo>
  <joint name="back_left_knee_joint" type="revolute">
    <axis rpy="-6.28318530718 0 0" xyz="1 0 0"/>
    <parent link="back_left_upperleg"/>
    <child link="back_left_lowerleg"/>
    <origin rpy="0 0 0" xyz="0 0 -0.315"/>
    <limit effort="60" lower="-2.61795" upper="0.02" velocity="6.0"/>
  </joint>
  <link name="back_left_foot">
    <visual>
      <origin rpy="-1.57079632679 0 0" xyz="0 0 0"/>
      <geometry>
        <mesh filename="package://dogbot_description/meshes/foot.dae" scale="1.0 1.0 1.0"/>
      </geometry>
    </visual>
    <collision>
      <origin rpy="0 0 0" xyz="0 -0.035 -0.3"/>
      <geometry>
        <sphere radius="0.028"/>
      </geometry>
    </collision>
    <inertial>
      <mass value="0.001"/>
      <origin rpy="0 0 0" xyz="0 0 0"/>
      <inertia ixx="1.66666666667e-10" ixy="0.0" ixz="0.0" iyy="1.66666666667e-10" iyz="0.0" izz="1.66666666667e-10"/>
    </inertial>
  </link>
  <joint name="back_left_foot_joint" type="fixed">
    <axis rpy="0 0 0" xyz="0 1 0"/>
    <parent link="back_left_lowerleg"/>
    <child link="back_left_foot"/>
    <origin rpy="0 0 0" xyz="0 0 0"/>
  </joint>
  
  
  <link name="FR_foot">
    <origin rpy="0 0 0" xyz="0 0 0"/>
  </link>
  <joint name="FR_joint" type="fixed">
    <parent link="back_left_foot"/>
    <child link="FR_foot"/>
    <origin rpy="0 0 -1.57" xyz="0 -0.035 -0.3"/>
  </joint>



  <gazebo reference="back_left_foot">
    <mu1>100</mu1>
    <mu2>100</mu2>
    <self_collide>0</self_collide>
    <material>Gazebo/Red</material>
    <kp value="1000000.0"/>
    <kd value="1.0"/>

    <collision>
      <surface>
        <contact>
          <ode>
            <min_depth>0.01</min_depth>
          </ode>
        </contact>
      </surface>
    </collision>
    <sensor name="back_left_foot_contactsensor_sensor" type="contact">
        <always_on>true</always_on>
        <material>Gazebo/Red</material>
        <contact>
        <collision>back_left_lowerleg_fixed_joint_lump__back_left_foot_collision_5</collision>
        </contact>
        <plugin name="back_left_foot_plugin" filename="libgazebo_ros_bumper.so">
        <bumperTopicName>dogbot/back_left_foot_contactsensor_state</bumperTopicName>
        <frameName>back_left_foot</frameName>
        </plugin>
    </sensor>

  </gazebo>


  <transmission name="back_left_roll_transmition">
    <type>transmission_interface/SimpleTransmission</type>
    <joint name="back_left_roll_joint">
      <hardwareInterface>hardware_interface/EffortJointInterface</hardwareInterface>
    </joint>
    <actuator name="back_left_roll_motor">
      <hardwareInterface>hardware_interface/EffortJointInterface</hardwareInterface>
      <mechanicalReduction>1</mechanicalReduction>
    </actuator>
  </transmission>
  <transmission name="back_left_pitch_transmition">
    <type>transmission_interface/SimpleTransmission</type>
    <joint name="back_left_pitch_joint">
      <hardwareInterface>hardware_interface/EffortJointInterface</hardwareInterface>
    </joint>
    <actuator name="back_left_pitch_motor">
      <hardwareInterface>hardware_interface/EffortJointInterface</hardwareInterface>
      <mechanicalReduction>1</mechanicalReduction>
    </actuator>
  </transmission>
  <transmission name="back_left_knee_transmition">
    <type>transmission_interface/SimpleTransmission</type>
    <joint name="back_left_knee_joint">
      <hardwareInterface>hardware_interface/EffortJointInterface</hardwareInterface>
    </joint>
    <actuator name="back_left_knee_motor">
      <hardwareInterface>hardware_interface/EffortJointInterface</hardwareInterface>
      <mechanicalReduction>1</mechanicalReduction>
    </actuator>
  </transmission>
  <link name="back_right_hip">
    <visual>
      <origin rpy="-1.57079632679 0.0 0" xyz="0 0 0"/>
      <geometry>
        <mesh filename="package://dogbot_description/meshes/hip.dae" scale="1.0 1.0 1.0"/>
      </geometry>
    </visual>
    <collision>
      <origin rpy="0 1.57079632679 0" xyz="0.02 0 0"/>
      <geometry>
        <cylinder length="0.08" radius="0.0525"/>
      </geometry>
    </collision>
    <inertial>
      <mass value="0.836"/>
      <origin rpy="0 0 0" xyz="0.0074 0 0"/>
      <inertia ixx="0.00213" ixy="0" ixz="0" iyy="0.00147" iyz="0" izz="0.00172"/>
    </inertial>
  </link>
  <!-- roll joint connects the hip to the body -->
  <joint name="back_right_roll_joint" type="revolute">
    <axis rpy="0 0 0" xyz="0 -1 0"/>
    <parent link="body"/>
    <child link="back_right_hip"/>
    <origin rpy="0 0 0" xyz="0.088 -0.2875 0"/>
    <limit effort="60" lower="-1.7453" upper="1.7453" velocity="6.0"/>
  </joint>
  <link name="back_right_upperleg">
    <visual>
      <origin rpy="-1.57079632679 0 0.0" xyz="0 0 0"/>
      <geometry>
        <mesh filename="package://dogbot_description/meshes/LegUpper_withCover.dae" scale="1.0 1.0 1.0"/>
      </geometry>
    </visual>
    <collision>
      <origin rpy="0 1.57079632679 0" xyz="0.03 0 0"/>
      <geometry>
        <cylinder length="0.13" radius="0.0525"/>
      </geometry>
    </collision>
    <collision>
      <origin rpy="0 0 0" xyz="0 0 -0.135"/>
      <geometry>
        <cylinder length="0.27" radius="0.033"/>
      </geometry>
    </collision>
    <collision>
      <origin rpy="0 0 0" xyz="0 0 -0.135"/>
      <geometry>
        <box size="0.025 0.084 0.27"/>
      </geometry>
    </collision>
    <collision>
      <origin rpy="0 0 0" xyz="0.046 0 -0.126"/>
      <geometry>
        <box size="0.026 0.074 0.138"/>
      </geometry>
    </collision>
    <collision>
      <origin rpy="0 1.57079632679 0" xyz="0.03 0 -0.315"/>
      <geometry>
        <cylinder length="0.018" radius="0.017"/>
      </geometry>
    </collision>
    <collision>
      <origin rpy="0 1.57079632679 0" xyz="-0.036 0 -0.315"/>
      <geometry>
        <cylinder length="0.013" radius="0.017"/>
      </geometry>
    </collision>
    <inertial>
      <mass value="1.851"/>
      <origin rpy="0 0 0" xyz="0.0418 0 -0.0517"/>
      <inertia ixx="0.0238" ixy="0" ixz="0" iyy="0.0252" iyz="0" izz="0.0044"/>
    </inertial>
  </link>
  <!-- pitch joint connects hip to upper leg -->
  <joint name="back_right_pitch_joint" type="revolute">
    <axis rpy="0 0 0" xyz="1 0 0"/>
    <parent link="back_right_hip"/>
    <child link="back_right_upperleg"/>
    <origin rpy="0 0 0" xyz="0.09875 0 0"/>
    <limit effort="60" lower="-3.14159265359" upper="1.57079632679" velocity="6.0"/>
  </joint>
  <link name="back_right_lowerleg">
    <visual>
      <origin rpy="-1.57079632679 0 0" xyz="0 0 0"/>
      <geometry>
        <mesh filename="package://dogbot_description/meshes/LegLower_nofoot.dae" scale="1.0 1.0 1.0"/>
      </geometry>
    </visual>
    <collision>
      <origin rpy="0 1.57079632679 0" xyz="0 0 0"/>
      <geometry>
        <cylinder length="0.033" radius="0.042"/>
      </geometry>
    </collision>
    <collision>
      <origin rpy="0 0 0" xyz="0.024 -0.0375 -0.0055"/>
      <geometry>
        <box size="0.02 0.017 0.065"/>
      </geometry>
    </collision>
    <collision>
      <origin rpy="0 0 0" xyz="-0.024 -0.0375 -0.0055"/>
      <geometry>
        <box size="0.02 0.017 0.065"/>
      </geometry>
    </collision>
    <collision>
      <origin rpy="0 0.04996 0" xyz="0.01575 -0.0375 -0.145"/>
      <geometry>
        <cylinder length="0.29" radius="0.006"/>
      </geometry>
    </collision>
    <collision>
      <origin rpy="0 -0.04996 0" xyz="-0.01575 -0.0375 -0.145"/>
      <geometry>
        <cylinder length="0.29" radius="0.006"/>
      </geometry>
    </collision>
    <inertial>
      <mass value="0.302"/>
      <origin rpy="0 0 0" xyz="0 -0.029 -0.1439"/>
      <inertia ixx="0.00527" ixy="0" ixz="0" iyy="0.00509" iyz="0" izz="0.0008"/>
    </inertial>
  </link>
  <gazebo reference="back_right_lowerleg">
    <mu1 value="2000.0"/>
    <mu2 value="1000.0"/>
    <kp value="1000000"/>
    <kd value="1.0"/>
    <selfCollide value="true"/>
  </gazebo>
  <joint name="back_right_knee_joint" type="revolute">
    <axis rpy="-6.28318530718 0 0" xyz="-1 0 0"/>
    <parent link="back_right_upperleg"/>
    <child link="back_right_lowerleg"/>
    <origin rpy="0 0 0" xyz="0 0 -0.315"/>
    <limit effort="60" lower="-0.02" upper="2.61795" velocity="6.0"/>
  </joint>
  <link name="back_right_foot">
    <visual>
      <origin rpy="-1.57079632679 0 0" xyz="0 0 0"/>
      <geometry>
        <mesh filename="package://dogbot_description/meshes/foot.dae" scale="1.0 1.0 1.0"/>
      </geometry>
    </visual>
    <collision>
      <origin rpy="0 0 0" xyz="0 -0.035 -0.3"/>
      <geometry>
        <sphere radius="0.028"/>
      </geometry>
    </collision>
    <inertial>
      <mass value="0.001"/>
      <origin rpy="0 0 0" xyz="0 0 0"/>
      <inertia ixx="1.66666666667e-10" ixy="0.0" ixz="0.0" iyy="1.66666666667e-10" iyz="0.0" izz="1.66666666667e-10"/>
    </inertial>
  </link>
  <joint name="back_right_foot_joint" type="fixed">
    <axis rpy="0 0 0" xyz="0 1 0"/>
    <parent link="back_right_lowerleg"/>
    <child link="back_right_foot"/>
    <origin rpy="0 0 0" xyz="0 0 0"/>
  </joint>


  <link name="FL_foot">
    <origin rpy="0 0 0" xyz="0 0 0"/>
  </link>
  <joint name="FL_joint" type="fixed">
    <parent link="back_right_foot"/>
    <child link="FL_foot"/>
    <origin rpy="0 0 -1.57" xyz="0 -0.035 -0.3"/>
  </joint>



  <gazebo reference="back_right_foot">
    <mu1>100</mu1>
    <mu2>100</mu2>
    <self_collide>0</self_collide>
    <material>Gazebo/Red</material>
    <kp value="1000000.0"/>
    <kd value="1.0"/>

    <collision>
      <surface>
        <contact>
          <ode>
            <min_depth>0.01</min_depth>
          </ode>
        </contact>
      </surface>
    </collision>
    <sensor name="back_right_foot_contactsensor_sensor" type="contact">
        <always_on>true</always_on>
        <material>Gazebo/Red</material>
        <contact>
        <collision>back_right_lowerleg_fixed_joint_lump__back_right_foot_collision_5</collision>
        </contact>
        <plugin name="back_right_foot_plugin" filename="libgazebo_ros_bumper.so">
        <bumperTopicName>dogbot/back_right_foot_contactsensor_state</bumperTopicName>
        <frameName>back_right_foot</frameName>
        </plugin>
    </sensor>

  </gazebo>



  <transmission name="back_right_roll_transmition">
    <type>transmission_interface/SimpleTransmission</type>
    <joint name="back_right_roll_joint">
      <hardwareInterface>hardware_interface/EffortJointInterface</hardwareInterface>
    </joint>
    <actuator name="back_right_roll_motor">
      <hardwareInterface>hardware_interface/EffortJointInterface</hardwareInterface>
      <mechanicalReduction>1</mechanicalReduction>
    </actuator>
  </transmission>
  <transmission name="back_right_pitch_transmition">
    <type>transmission_interface/SimpleTransmission</type>
    <joint name="back_right_pitch_joint">
      <hardwareInterface>hardware_interface/EffortJointInterface</hardwareInterface>
    </joint>
    <actuator name="back_right_pitch_motor">
      <hardwareInterface>hardware_interface/EffortJointInterface</hardwareInterface>
      <mechanicalReduction>1</mechanicalReduction>
    </actuator>
  </transmission>
  <transmission name="back_right_knee_transmition">
    <type>transmission_interface/SimpleTransmission</type>
    <joint name="back_right_knee_joint">
      <hardwareInterface>hardware_interface/EffortJointInterface</hardwareInterface>
    </joint>
    <actuator name="back_right_knee_motor">
      <hardwareInterface>hardware_interface/EffortJointInterface</hardwareInterface>
      <mechanicalReduction>1</mechanicalReduction>
    </actuator>
  </transmission>
  <link name="front_left_hip">
    <visual>
      <origin rpy="-1.57079632679 -3.14159265359 0" xyz="0 0 0"/>
      <geometry>
        <mesh filename="package://dogbot_description/meshes/hip.dae" scale="1.0 1.0 1.0"/>
      </geometry>
    </visual>
    <collision>
      <origin rpy="0 1.57079632679 0" xyz="-0.02 0 0"/>
      <geometry>
        <cylinder length="0.08" radius="0.0525"/>
      </geometry>
    </collision>
    <inertial>
      <mass value="0.836"/>
      <origin rpy="0 0 0" xyz="-0.0074 0 0"/>
      <inertia ixx="0.00213" ixy="0" ixz="0" iyy="0.00147" iyz="0" izz="0.00172"/>
    </inertial>
  </link>
  <!-- roll joint connects the hip to the body -->
  <joint name="front_left_roll_joint" type="revolute">
    <axis rpy="0 0 0" xyz="0 1 0"/>
    <parent link="body"/>
    <child link="front_left_hip"/>
    <origin rpy="0 0 0" xyz="-0.088 0.2875 0"/>
    <limit effort="60" lower="-1.7453" upper="1.7453" velocity="6.0"/>
  </joint>
  <link name="front_left_upperleg">
    <visual>
      <origin rpy="-1.57079632679 0 -3.14159265359" xyz="0 0 0"/>
      <geometry>
        <mesh filename="package://dogbot_description/meshes/LegUpper_withCover.dae" scale="1.0 1.0 1.0"/>
      </geometry>
    </visual>
    <collision>
      <origin rpy="0 1.57079632679 0" xyz="-0.03 0 0"/>
      <geometry>
        <cylinder length="0.13" radius="0.0525"/>
      </geometry>
    </collision>
    <collision>
      <origin rpy="0 0 0" xyz="0 0 -0.135"/>
      <geometry>
        <cylinder length="0.27" radius="0.033"/>
      </geometry>
    </collision>
    <collision>
      <origin rpy="0 0 0" xyz="0 0 -0.135"/>
      <geometry>
        <box size="0.025 0.084 0.27"/>
      </geometry>
    </collision>
    <collision>
      <origin rpy="0 0 0" xyz="-0.046 0 -0.126"/>
      <geometry>
        <box size="0.026 0.074 0.138"/>
      </geometry>
    </collision>
    <collision>
      <origin rpy="0 1.57079632679 0" xyz="-0.03 0 -0.315"/>
      <geometry>
        <cylinder length="0.018" radius="0.017"/>
      </geometry>
    </collision>
    <collision>
      <origin rpy="0 1.57079632679 0" xyz="0.036 0 -0.315"/>
      <geometry>
        <cylinder length="0.013" radius="0.017"/>
      </geometry>
    </collision>
    <inertial>
      <mass value="1.851"/>
      <origin rpy="0 0 0" xyz="-0.0418 0 -0.0517"/>
      <inertia ixx="0.0238" ixy="0" ixz="0" iyy="0.0252" iyz="0" izz="0.0044"/>
    </inertial>
  </link>
  <!-- pitch joint connects hip to upper leg -->
  <joint name="front_left_pitch_joint" type="revolute">
    <axis rpy="0 0 0" xyz="-1 0 0"/>
    <parent link="front_left_hip"/>
    <child link="front_left_upperleg"/>
    <origin rpy="0 0 0" xyz="-0.09875 0 0"/>
    <limit effort="60" lower="-1.57079632679" upper="3.14159265359" velocity="6.0"/>
  </joint>
  <link name="front_left_lowerleg">
    <visual>
      <origin rpy="-1.57079632679 0 0" xyz="0 0 0"/>
      <geometry>
        <mesh filename="package://dogbot_description/meshes/LegLower_nofoot.dae" scale="1.0 1.0 1.0"/>
      </geometry>
    </visual>
    <collision>
      <origin rpy="0 1.57079632679 0" xyz="0 0 0"/>
      <geometry>
        <cylinder length="0.033" radius="0.042"/>
      </geometry>
    </collision>
    <collision>
      <origin rpy="0 0 0" xyz="0.024 -0.0375 -0.0055"/>
      <geometry>
        <box size="0.02 0.017 0.065"/>
      </geometry>
    </collision>
    <collision>
      <origin rpy="0 0 0" xyz="-0.024 -0.0375 -0.0055"/>
      <geometry>
        <box size="0.02 0.017 0.065"/>
      </geometry>
    </collision>
    <collision>
      <origin rpy="0 0.04996 0" xyz="0.01575 -0.0375 -0.145"/>
      <geometry>
        <cylinder length="0.29" radius="0.006"/>
      </geometry>
    </collision>
    <collision>
      <origin rpy="0 -0.04996 0" xyz="-0.01575 -0.0375 -0.145"/>
      <geometry>
        <cylinder length="0.29" radius="0.006"/>
      </geometry>
    </collision>
    <inertial>
      <mass value="0.302"/>
      <origin rpy="0 0 0" xyz="0 -0.029 -0.1439"/>
      <inertia ixx="0.00527" ixy="0" ixz="0" iyy="0.00509" iyz="0" izz="0.0008"/>
    </inertial>
  </link>
  <gazebo reference="front_left_lowerleg">
    <mu1 value="2000.0"/>
    <mu2 value="1000.0"/>
    <kp value="1000000"/>
    <kd value="1.0"/>
    <selfCollide value="true"/>
  </gazebo>
  <joint name="front_left_knee_joint" type="revolute">
    <axis rpy="-6.28318530718 0 0" xyz="1 0 0"/>
    <parent link="front_left_upperleg"/>
    <child link="front_left_lowerleg"/>
    <origin rpy="0 0 0" xyz="0 0 -0.315"/>
    <limit effort="60" lower="-2.61795" upper="0.02" velocity="6.0"/>
  </joint>
  <link name="front_left_foot">
    <visual>
      <origin rpy="-1.57079632679 0 0" xyz="0 0 0"/>
      <geometry>
        <mesh filename="package://dogbot_description/meshes/foot.dae" scale="1.0 1.0 1.0"/>
      </geometry>
    </visual>
    <collision>
      <origin rpy="0 0 0" xyz="0 -0.035 -0.3"/>
      <geometry>
        <sphere radius="0.028"/>
      </geometry>
    </collision>
    <inertial>
      <mass value="0.001"/>
      <origin rpy="0 0 0" xyz="0 0 0"/>
      <inertia ixx="1.66666666667e-10" ixy="0.0" ixz="0.0" iyy="1.66666666667e-10" iyz="0.0" izz="1.66666666667e-10"/>
    </inertial>
  </link>
  <joint name="front_left_foot_joint" type="fixed">
    <axis rpy="0 0 0" xyz="0 1 0"/>
    <parent link="front_left_lowerleg"/>
    <child link="front_left_foot"/>
    <origin rpy="0 0 0" xyz="0 0 0"/>
  </joint>


  <link name="RR_foot">
    <origin rpy="0 0 0" xyz="0 0 0"/>
  </link>
  <joint name="RR_joint" type="fixed">
    <parent link="front_left_foot"/>
    <child link="RR_foot"/>
    <origin rpy="0 0 -1.57" xyz="0 -0.035 -0.3"/>
  </joint>


  <gazebo reference="front_left_foot">
    <mu1>100</mu1>
    <mu2>100</mu2>
    <self_collide>0</self_collide>
    <material>Gazebo/Red</material>
    <kp value="1000000.0"/>
    <kd value="1.0"/>

    <collision>
      <surface>
        <contact>
          <ode>
            <min_depth>0.01</min_depth>
          </ode>
        </contact>
      </surface>
    </collision>

    <sensor name="front_left_foot_contactsensor_sensor" type="contact">
        <always_on>true</always_on>
        <material>Gazebo/Red</material>
        <contact>
        <collision>front_left_lowerleg_fixed_joint_lump__front_left_foot_collision_5</collision>
        </contact>
        <plugin name="front_left_foot_plugin" filename="libgazebo_ros_bumper.so">
        <bumperTopicName>dogbot/front_left_foot_contactsensor_state</bumperTopicName>
        <frameName>front_left_foot</frameName>
        </plugin>
    </sensor>



  </gazebo>




  <transmission name="front_left_roll_transmition">
    <type>transmission_interface/SimpleTransmission</type>
    <joint name="front_left_roll_joint">
      <hardwareInterface>hardware_interface/EffortJointInterface</hardwareInterface>
    </joint>
    <actuator name="front_left_roll_motor">
      <hardwareInterface>hardware_interface/EffortJointInterface</hardwareInterface>
      <mechanicalReduction>1</mechanicalReduction>
    </actuator>
  </transmission>
  <transmission name="front_left_pitch_transmition">
    <type>transmission_interface/SimpleTransmission</type>
    <joint name="front_left_pitch_joint">
      <hardwareInterface>hardware_interface/EffortJointInterface</hardwareInterface>
    </joint>
    <actuator name="front_left_pitch_motor">
      <hardwareInterface>hardware_interface/EffortJointInterface</hardwareInterface>
      <mechanicalReduction>1</mechanicalReduction>
    </actuator>
  </transmission>
  <transmission name="front_left_knee_transmition">
    <type>transmission_interface/SimpleTransmission</type>
    <joint name="front_left_knee_joint">
      <hardwareInterface>hardware_interface/EffortJointInterface</hardwareInterface>
    </joint>
    <actuator name="front_left_knee_motor">
      <hardwareInterface>hardware_interface/EffortJointInterface</hardwareInterface>
      <mechanicalReduction>1</mechanicalReduction>
    </actuator>
  </transmission>
  <link name="front_right_hip">
    <visual>
      <origin rpy="-1.57079632679 0.0 0" xyz="0 0 0"/>
      <geometry>
        <mesh filename="package://dogbot_description/meshes/hip.dae" scale="1.0 1.0 1.0"/>
      </geometry>
    </visual>
    <collision>
      <origin rpy="0 1.57079632679 0" xyz="0.02 0 0"/>
      <geometry>
        <cylinder length="0.08" radius="0.0525"/>
      </geometry>
    </collision>
    <inertial>
      <mass value="0.836"/>
      <origin rpy="0 0 0" xyz="0.0074 0 0"/>
      <inertia ixx="0.00213" ixy="0" ixz="0" iyy="0.00147" iyz="0" izz="0.00172"/>
    </inertial>
  </link>
  <!-- roll joint connects the hip to the body -->
  <joint name="front_right_roll_joint" type="revolute">
    <axis rpy="0 0 0" xyz="0 1 0"/>
    <parent link="body"/>
    <child link="front_right_hip"/>
    <origin rpy="0 0 0" xyz="0.088 0.2875 0"/>
    <limit effort="60" lower="-1.7453" upper="1.7453" velocity="6.0"/>
  </joint>
  <link name="front_right_upperleg">
    <visual>
      <origin rpy="-1.57079632679 0 0.0" xyz="0 0 0"/>
      <geometry>
        <mesh filename="package://dogbot_description/meshes/LegUpper_withCover.dae" scale="1.0 1.0 1.0"/>
      </geometry>
    </visual>
    <collision>
      <origin rpy="0 1.57079632679 0" xyz="0.03 0 0"/>
      <geometry>
        <cylinder length="0.13" radius="0.0525"/>
      </geometry>
    </collision>
    <collision>
      <origin rpy="0 0 0" xyz="0 0 -0.135"/>
      <geometry>
        <cylinder length="0.27" radius="0.033"/>
      </geometry>
    </collision>
    <collision>
      <origin rpy="0 0 0" xyz="0 0 -0.135"/>
      <geometry>
        <box size="0.025 0.084 0.27"/>
      </geometry>
    </collision>
    <collision>
      <origin rpy="0 0 0" xyz="0.046 0 -0.126"/>
      <geometry>
        <box size="0.026 0.074 0.138"/>
      </geometry>
    </collision>
    <collision>
      <origin rpy="0 1.57079632679 0" xyz="0.03 0 -0.315"/>
      <geometry>
        <cylinder length="0.018" radius="0.017"/>
      </geometry>
    </collision>
    <collision>
      <origin rpy="0 1.57079632679 0" xyz="-0.036 0 -0.315"/>
      <geometry>
        <cylinder length="0.013" radius="0.017"/>
      </geometry>
    </collision>
    <inertial>
      <mass value="1.851"/>
      <origin rpy="0 0 0" xyz="0.0418 0 -0.0517"/>
      <inertia ixx="0.0238" ixy="0" ixz="0" iyy="0.0252" iyz="0" izz="0.0044"/>
    </inertial>
  </link>
  <!-- pitch joint connects hip to upper leg -->
  <joint name="front_right_pitch_joint" type="revolute">
    <axis rpy="0 0 0" xyz="1 0 0"/>
    <parent link="front_right_hip"/>
    <child link="front_right_upperleg"/>
    <origin rpy="0 0 0" xyz="0.09875 0 0"/>
    <limit effort="60" lower="-3.14159265359" upper="1.57079632679" velocity="6.0"/>
  </joint>
  <link name="front_right_lowerleg">
    <visual>
      <origin rpy="-1.57079632679 0 0" xyz="0 0 0"/>
      <geometry>
        <mesh filename="package://dogbot_description/meshes/LegLower_nofoot.dae" scale="1.0 1.0 1.0"/>
      </geometry>
    </visual>
    <collision>
      <origin rpy="0 1.57079632679 0" xyz="0 0 0"/>
      <geometry>
        <cylinder length="0.033" radius="0.042"/>
      </geometry>
    </collision>
    <collision>
      <origin rpy="0 0 0" xyz="0.024 -0.0375 -0.0055"/>
      <geometry>
        <box size="0.02 0.017 0.065"/>
      </geometry>
    </collision>
    <collision>
      <origin rpy="0 0 0" xyz="-0.024 -0.0375 -0.0055"/>
      <geometry>
        <box size="0.02 0.017 0.065"/>
      </geometry>
    </collision>
    <collision>
      <origin rpy="0 0.04996 0" xyz="0.01575 -0.0375 -0.145"/>
      <geometry>
        <cylinder length="0.29" radius="0.006"/>
      </geometry>
    </collision>
    <collision>
      <origin rpy="0 -0.04996 0" xyz="-0.01575 -0.0375 -0.145"/>
      <geometry>
        <cylinder length="0.29" radius="0.006"/>
      </geometry>
    </collision>
    <inertial>
      <mass value="0.302"/>
      <origin rpy="0 0 0" xyz="0 -0.029 -0.1439"/>
      <inertia ixx="0.00527" ixy="0" ixz="0" iyy="0.00509" iyz="0" izz="0.0008"/>
    </inertial>
  </link>
  <gazebo reference="front_right_lowerleg">
    <mu1 value="2000.0"/>
    <mu2 value="1000.0"/>
    <kp value="1000000"/>
    <kd value="1.0"/>
    <selfCollide value="true"/>
  </gazebo>
  <joint name="front_right_knee_joint" type="revolute">
    <axis rpy="-6.28318530718 0 0" xyz="-1 0 0"/>
    <parent link="front_right_upperleg"/>
    <child link="front_right_lowerleg"/>
    <origin rpy="0 0 0" xyz="0 0 -0.315"/>
    <limit effort="60" lower="-0.02" upper="2.61795" velocity="6.0"/>
  </joint>
  <link name="front_right_foot">
    <visual>
      <origin rpy="-1.57079632679 0 0" xyz="0 0 0"/>
      <geometry>
        <mesh filename="package://dogbot_description/meshes/foot.dae" scale="1.0 1.0 1.0"/>
      </geometry>
    </visual>
    <collision>
      <origin rpy="0 0 0" xyz="0 -0.035 -0.3"/>
      <geometry>
        <sphere radius="0.028"/>
      </geometry>
    </collision>
    <inertial>
      <mass value="0.001"/>
      <origin rpy="0 0 0" xyz="0 0 0"/>
      <inertia ixx="1.66666666667e-10" ixy="0.0" ixz="0.0" iyy="1.66666666667e-10" iyz="0.0" izz="1.66666666667e-10"/>
    </inertial>
  </link>
  <joint name="front_right_foot_joint" type="fixed">
    <axis rpy="0 0 0" xyz="0 1 0"/>
    <parent link="front_right_lowerleg"/>
    <child link="front_right_foot"/>
    <origin rpy="0 0 0" xyz="0 0 0"/>
  </joint>


  <link name="RL_foot">
    <origin rpy="0 0 0" xyz="0 0 0"/>
  </link>
  <joint name="RL_joint" type="fixed">
    <parent link="front_right_foot"/>
    <child link="RL_foot"/>
    <origin rpy="0 0 -1.57" xyz="0 -0.035 -0.3"/>
  </joint>


  <gazebo reference="front_right_foot">
    <mu1>100</mu1>
    <mu2>100</mu2>
    <self_collide>0</self_collide>
    <material>Gazebo/Red</material>
    <kp value="1000000.0"/>
    <kd value="1.0"/>

    <collision>
      <surface>
        <contact>
          <ode>
            <min_depth>0.01</min_depth>
          </ode>
        </contact>
      </surface>
    </collision>
  
    <sensor name="front_right_foot_contactsensor_sensor" type="contact">
        <always_on>true</always_on>
        <material>Gazebo/Red</material>
        <contact>
        <collision>front_right_lowerleg_fixed_joint_lump__front_right_foot_collision_5</collision>
        </contact>
        <plugin name="front_right_foot_plugin" filename="libgazebo_ros_bumper.so">
        <bumperTopicName>dogbot/front_right_foot_contactsensor_state</bumperTopicName>
        <frameName>front_right_foot</frameName>
        </plugin>
    </sensor>
  </gazebo>



  <transmission name="front_right_roll_transmition">
    <type>transmission_interface/SimpleTransmission</type>
    <joint name="front_right_roll_joint">
      <hardwareInterface>hardware_interface/EffortJointInterface</hardwareInterface>
    </joint>
    <actuator name="front_right_roll_motor">
      <hardwareInterface>hardware_interface/EffortJointInterface</hardwareInterface>
      <mechanicalReduction>1</mechanicalReduction>
    </actuator>
  </transmission>
  <transmission name="front_right_pitch_transmition">
    <type>transmission_interface/SimpleTransmission</type>
    <joint name="front_right_pitch_joint">
      <hardwareInterface>hardware_interface/EffortJointInterface</hardwareInterface>
    </joint>
    <actuator name="front_right_pitch_motor">
      <hardwareInterface>hardware_interface/EffortJointInterface</hardwareInterface>
      <mechanicalReduction>1</mechanicalReduction>
    </actuator>
  </transmission>
  <transmission name="front_right_knee_transmition">
    <type>transmission_interface/SimpleTransmission</type>
    <joint name="front_right_knee_joint">
      <hardwareInterface>hardware_interface/EffortJointInterface</hardwareInterface>
    </joint>
    <actuator name="front_right_knee_motor">
      <hardwareInterface>hardware_interface/EffortJointInterface</hardwareInterface>
      <mechanicalReduction>1</mechanicalReduction>
    </actuator>
  </transmission>
  <gazebo>
    <plugin filename="libhector_gazebo_ros_imu.so" name="imu_plugin">
      <alwaysOn>true</alwaysOn>
      <bodyName>body</bodyName>
      <robotNamespace>dogbot</robotNamespace>
      <topicName>imu</topicName>
      <serviceName>imu_service</serviceName>
      <gaussianNoise>0.0</gaussianNoise>
      <updateRate>20.0</updateRate>
    </plugin>
    <plugin filename="libhector_gazebo_ros_gps.so" name="gps_plugin">
      <alwaysOn>true</alwaysOn>
      <bodyName>body</bodyName>
      <robotNamespace>dogbot</robotNamespace>
      <topicName>gps</topicName>
      <serviceName>imu_service</serviceName>
      <updateRate>100</updateRate>
      <referenceLatitude>51.5</referenceLatitude>
      <referenceLongitude>0.1278</referenceLongitude>
    </plugin>
  </gazebo>
  <!-- Gazebo plugin for ROS Control -->
  <gazebo>
    <plugin filename="libgazebo_ros_control.so" name="gazebo_ros_control">
      <robotNamespace>/dogbot</robotNamespace>
    </plugin>
  </gazebo>
</robot>

