<sdf version='1.7'>
  <model name='dogbot'>
    <link name='base'>
      <inertial>
        <pose>0 0 0 0 -0 0</pose>
        <mass>9.301</mass>
        <inertia>
          <ixx>0.0910002</ixx>
          <ixy>0.000254028</ixy>
          <ixz>0</ixz>
          <iyy>0.41</iyy>
          <iyz>0</iyz>
          <izz>0.482</izz>
        </inertia>
      </inertial>
      <collision name='base_fixed_joint_lump__body_collision'>
        <pose>0 0 0 0 -0 1.57</pose>
        <geometry>
          <box>
            <size>0.177 0.433 0.105</size>
          </box>
        </geometry>
        <surface>
          <contact>
            <ode>
              <kp>1e+06</kp>
              <kd>1</kd>
            </ode>
          </contact>
          <friction>
            <ode>
              <mu>200</mu>
              <mu2>100</mu2>
            </ode>
          </friction>
        </surface>
      </collision>
      <collision name='base_fixed_joint_lump__body_collision_1'>
        <pose>7e-05 0.0885 0 1.5708 0 1.57</pose>
        <geometry>
          <cylinder>
            <length>0.433</length>
            <radius>0.0525</radius>
          </cylinder>
        </geometry>
        <surface>
          <contact>
            <ode>
              <kp>1e+06</kp>
              <kd>1</kd>
            </ode>
          </contact>
          <friction>
            <ode>
              <mu>200</mu>
              <mu2>100</mu2>
            </ode>
          </friction>
        </surface>
      </collision>
      <collision name='base_fixed_joint_lump__body_collision_2'>
        <pose>-7e-05 -0.0885 0 1.5708 0 1.57</pose>
        <geometry>
          <cylinder>
            <length>0.433</length>
            <radius>0.0525</radius>
          </cylinder>
        </geometry>
        <surface>
          <contact>
            <ode>
              <kp>1e+06</kp>
              <kd>1</kd>
            </ode>
          </contact>
          <friction>
            <ode>
              <mu>200</mu>
              <mu2>100</mu2>
            </ode>
          </friction>
        </surface>
      </collision>
      <collision name='base_fixed_joint_lump__body_collision_3'>
        <pose>-0.2825 0.000225 0 0 -0 1.57</pose>
        <geometry>
          <box>
            <size>0.035 0.132 0.105</size>
          </box>
        </geometry>
        <surface>
          <contact>
            <ode>
              <kp>1e+06</kp>
              <kd>1</kd>
            </ode>
          </contact>
          <friction>
            <ode>
              <mu>200</mu>
              <mu2>100</mu2>
            </ode>
          </friction>
        </surface>
      </collision>
      <collision name='base_fixed_joint_lump__body_collision_4'>
        <pose>0.2825 -0.000225 0 0 -0 1.57</pose>
        <geometry>
          <box>
            <size>0.035 0.132 0.105</size>
          </box>
        </geometry>
        <surface>
          <contact>
            <ode>
              <kp>1e+06</kp>
              <kd>1</kd>
            </ode>
          </contact>
          <friction>
            <ode>
              <mu>200</mu>
              <mu2>100</mu2>
            </ode>
          </friction>
        </surface>
      </collision>
      <collision name='base_fixed_joint_lump__body_collision_5'>
        <pose>-0.3975 0.000317 0 0 -0 1.57</pose>
        <geometry>
          <box>
            <size>0.177 0.08 0.105</size>
          </box>
        </geometry>
        <surface>
          <contact>
            <ode>
              <kp>1e+06</kp>
              <kd>1</kd>
            </ode>
          </contact>
          <friction>
            <ode>
              <mu>200</mu>
              <mu2>100</mu2>
            </ode>
          </friction>
        </surface>
      </collision>
      <collision name='base_fixed_joint_lump__body_collision_6'>
        <pose>-0.397429 0.088817 0 1.5708 0 1.57</pose>
        <geometry>
          <cylinder>
            <length>0.08</length>
            <radius>0.0525</radius>
          </cylinder>
        </geometry>
        <surface>
          <contact>
            <ode>
              <kp>1e+06</kp>
              <kd>1</kd>
            </ode>
          </contact>
          <friction>
            <ode>
              <mu>200</mu>
              <mu2>100</mu2>
            </ode>
          </friction>
        </surface>
      </collision>
      <collision name='base_fixed_joint_lump__body_collision_7'>
        <pose>-0.39757 -0.088183 0 1.5708 0 1.57</pose>
        <geometry>
          <cylinder>
            <length>0.08</length>
            <radius>0.0525</radius>
          </cylinder>
        </geometry>
        <surface>
          <contact>
            <ode>
              <kp>1e+06</kp>
              <kd>1</kd>
            </ode>
          </contact>
          <friction>
            <ode>
              <mu>200</mu>
              <mu2>100</mu2>
            </ode>
          </friction>
        </surface>
      </collision>
      <collision name='base_fixed_joint_lump__body_collision_8'>
        <pose>0.3975 -0.000317 0 0 -0 1.57</pose>
        <geometry>
          <box>
            <size>0.177 0.08 0.105</size>
          </box>
        </geometry>
        <surface>
          <contact>
            <ode>
              <kp>1e+06</kp>
              <kd>1</kd>
            </ode>
          </contact>
          <friction>
            <ode>
              <mu>200</mu>
              <mu2>100</mu2>
            </ode>
          </friction>
        </surface>
      </collision>
      <collision name='base_fixed_joint_lump__body_collision_9'>
        <pose>0.39757 0.088183 0 1.5708 0 1.57</pose>
        <geometry>
          <cylinder>
            <length>0.08</length>
            <radius>0.0525</radius>
          </cylinder>
        </geometry>
        <surface>
          <contact>
            <ode>
              <kp>1e+06</kp>
              <kd>1</kd>
            </ode>
          </contact>
          <friction>
            <ode>
              <mu>200</mu>
              <mu2>100</mu2>
            </ode>
          </friction>
        </surface>
      </collision>
      <collision name='base_fixed_joint_lump__body_collision_10'>
        <pose>0.397429 -0.088817 0 1.5708 0 1.57</pose>
        <geometry>
          <cylinder>
            <length>0.08</length>
            <radius>0.0525</radius>
          </cylinder>
        </geometry>
        <surface>
          <contact>
            <ode>
              <kp>1e+06</kp>
              <kd>1</kd>
            </ode>
          </contact>
          <friction>
            <ode>
              <mu>200</mu>
              <mu2>100</mu2>
            </ode>
          </friction>
        </surface>
      </collision>
      <collision name='base_fixed_joint_lump__camera_link_collision_11'>
        <pose>0.413884 0 -0.019729 0 0.1919 0</pose>
        <geometry>
          <box>
            <size>0.02505 0.09 0.025</size>
          </box>
        </geometry>
        <surface>
          <contact>
            <ode>
              <kp>1e+13</kp>
              <kd>1</kd>
            </ode>
          </contact>
          <friction>
            <ode>
              <mu2>1</mu2>
              <fdir1>0 0 0</fdir1>
            </ode>
          </friction>
        </surface>
      </collision>
      <visual name='base_fixed_joint_lump__body_visual'>
        <pose>0 0 0 -1.5708 -0 1.57</pose>
        <geometry>
          <mesh>
            <scale>1 1 1</scale>
            <uri>model://dogbot_description/meshes/body.dae</uri>
          </mesh>
        </geometry>
      </visual>
      <visual name='base_fixed_joint_lump__bodytext_visual_1'>
        <pose>0 0 0 -1.5708 -0 1.57</pose>
        <geometry>
          <mesh>
            <scale>1 1 1</scale>
            <uri>model://dogbot_description/meshes/bodyTEXT.dae</uri>
          </mesh>
        </geometry>
      </visual>
      <visual name='base_fixed_joint_lump__camera_link_visual_2'>
        <pose>0.428511 0 -0.022571 1.7627 0 1.5708</pose>
        <geometry>
          <mesh>
            <scale>1 1 1</scale>
            <uri>model://realsense2_description/meshes/d435.dae</uri>
          </mesh>
        </geometry>
      </visual>
      <self_collide>0</self_collide>
      <enable_wind>0</enable_wind>
      <kinematic>0</kinematic>
      <gravity>1</gravity>
      <sensor name='cameracolor' type='camera'>
        <camera name='camera'>
          <horizontal_fov>1.5</horizontal_fov>
          <image>
            <width>1280</width>
            <height>720</height>
            <format>RGB_INT8</format>
          </image>
          <clip>
            <near>0.1</near>
            <far>100</far>
          </clip>
          <noise>
            <type>gaussian</type>
            <mean>0</mean>
            <stddev>0.007</stddev>
          </noise>
        </camera>
        <always_on>1</always_on>
        <update_rate>30</update_rate>
        <visualize>0</visualize>
        <pose>0.413884 0.0175 -0.01973 0 0.1919 0</pose>
      </sensor>
      <sensor name='cameraired1' type='camera'>
        <camera name='camera'>
          <horizontal_fov>1.48702</horizontal_fov>
          <image>
            <width>1280</width>
            <height>720</height>
            <format>L_INT8</format>
          </image>
          <clip>
            <near>0.1</near>
            <far>100</far>
          </clip>
          <noise>
            <type>gaussian</type>
            <mean>0</mean>
            <stddev>0.05</stddev>
          </noise>
        </camera>
        <always_on>0</always_on>
        <update_rate>90</update_rate>
        <visualize>0</visualize>
        <pose>0.413884 0.0175 -0.01973 0 0.1919 0</pose>
      </sensor>
      <sensor name='cameraired2' type='camera'>
        <camera name='camera'>
          <horizontal_fov>1.48702</horizontal_fov>
          <image>
            <width>1280</width>
            <height>720</height>
            <format>L_INT8</format>
          </image>
          <clip>
            <near>0.1</near>
            <far>100</far>
          </clip>
          <noise>
            <type>gaussian</type>
            <mean>0</mean>
            <stddev>0.05</stddev>
          </noise>
        </camera>
        <always_on>0</always_on>
        <update_rate>90</update_rate>
        <visualize>0</visualize>
        <pose>0.413884 0.0175 -0.01973 0 0.1919 0</pose>
      </sensor>
      <sensor name='cameradepth' type='depth'>
        <camera name='camera'>
          <horizontal_fov>1.5</horizontal_fov>
          <image>
            <width>1280</width>
            <height>720</height>
          </image>
          <clip>
            <near>0.1</near>
            <far>100</far>
          </clip>
          <noise>
            <type>gaussian</type>
            <mean>0</mean>
            <stddev>0.1</stddev>
          </noise>
        </camera>
        <always_on>1</always_on>
        <update_rate>90</update_rate>
        <visualize>0</visualize>
        <pose>0.413884 0.0175 -0.01973 0 0.1919 0</pose>
      </sensor>
    </link>
    <joint name='back_left_roll_joint' type='revolute'>
      <pose relative_to='base'>0.28743 -0.088229 0 0 -0 1.57</pose>
      <parent>base</parent>
      <child>back_left_hip</child>
      <axis>
        <xyz>0 -1 0</xyz>
        <limit>
          <lower>-1.7453</lower>
          <upper>1.7453</upper>
          <effort>60</effort>
          <velocity>6</velocity>
        </limit>
        <dynamics>
          <spring_reference>0</spring_reference>
          <spring_stiffness>0</spring_stiffness>
        </dynamics>
      </axis>
    </joint>
    <link name='back_left_hip'>
      <pose relative_to='back_left_roll_joint'>0 0 0 0 -0 0</pose>
      <inertial>
        <pose>-0.0074 0 0 0 -0 0</pose>
        <mass>0.836</mass>
        <inertia>
          <ixx>0.00213</ixx>
          <ixy>0</ixy>
          <ixz>0</ixz>
          <iyy>0.00147</iyy>
          <iyz>0</iyz>
          <izz>0.00172</izz>
        </inertia>
      </inertial>
      <collision name='back_left_hip_collision'>
        <pose>-0.02 0 0 0 1.5708 0</pose>
        <geometry>
          <cylinder>
            <length>0.08</length>
            <radius>0.0525</radius>
          </cylinder>
        </geometry>
      </collision>
      <visual name='back_left_hip_visual'>
        <pose>0 0 0 1.5708 0 -3.14159</pose>
        <geometry>
          <mesh>
            <scale>1 1 1</scale>
            <uri>model://dogbot_description/meshes/hip.dae</uri>
          </mesh>
        </geometry>
      </visual>
    </link>
    <joint name='back_left_pitch_joint' type='revolute'>
      <pose relative_to='back_left_hip'>-0.09875 0 0 0 -0 0</pose>
      <parent>back_left_hip</parent>
      <child>back_left_upperleg</child>
      <axis>
        <xyz>-1 0 0</xyz>
        <limit>
          <lower>-1.5708</lower>
          <upper>3.14159</upper>
          <effort>60</effort>
          <velocity>6</velocity>
        </limit>
        <dynamics>
          <spring_reference>0</spring_reference>
          <spring_stiffness>0</spring_stiffness>
        </dynamics>
      </axis>
    </joint>
    <link name='back_left_upperleg'>
      <pose relative_to='back_left_pitch_joint'>0 0 0 0 -0 0</pose>
      <inertial>
        <pose>-0.0418 0 -0.0517 0 -0 0</pose>
        <mass>1.851</mass>
        <inertia>
          <ixx>0.0238</ixx>
          <ixy>0</ixy>
          <ixz>0</ixz>
          <iyy>0.0252</iyy>
          <iyz>0</iyz>
          <izz>0.0044</izz>
        </inertia>
      </inertial>
      <collision name='back_left_upperleg_collision'>
        <pose>-0.03 0 0 0 1.5708 0</pose>
        <geometry>
          <cylinder>
            <length>0.13</length>
            <radius>0.0525</radius>
          </cylinder>
        </geometry>
      </collision>
      <collision name='back_left_upperleg_collision_1'>
        <pose>0 0 -0.135 0 -0 0</pose>
        <geometry>
          <cylinder>
            <length>0.27</length>
            <radius>0.033</radius>
          </cylinder>
        </geometry>
      </collision>
      <collision name='back_left_upperleg_collision_2'>
        <pose>0 0 -0.135 0 -0 0</pose>
        <geometry>
          <box>
            <size>0.025 0.084 0.27</size>
          </box>
        </geometry>
      </collision>
      <collision name='back_left_upperleg_collision_3'>
        <pose>-0.046 0 -0.126 0 -0 0</pose>
        <geometry>
          <box>
            <size>0.026 0.074 0.138</size>
          </box>
        </geometry>
      </collision>
      <collision name='back_left_upperleg_collision_4'>
        <pose>-0.03 0 -0.315 0 1.5708 0</pose>
        <geometry>
          <cylinder>
            <length>0.018</length>
            <radius>0.017</radius>
          </cylinder>
        </geometry>
      </collision>
      <collision name='back_left_upperleg_collision_5'>
        <pose>0.036 0 -0.315 0 1.5708 0</pose>
        <geometry>
          <cylinder>
            <length>0.013</length>
            <radius>0.017</radius>
          </cylinder>
        </geometry>
      </collision>
      <visual name='back_left_upperleg_visual'>
        <pose>0 0 0 -1.5708 -0 3.14159</pose>
        <geometry>
          <mesh>
            <scale>1 1 1</scale>
            <uri>model://dogbot_description/meshes/LegUpper_withCover.dae</uri>
          </mesh>
        </geometry>
      </visual>
    </link>
    <joint name='back_left_knee_joint' type='revolute'>
      <pose relative_to='back_left_upperleg'>0 0 -0.315 0 -0 0</pose>
      <parent>back_left_upperleg</parent>
      <child>back_left_lowerleg</child>
      <axis>
        <xyz>1 0 0</xyz>
        <limit>
          <lower>-2.61795</lower>
          <upper>0.02</upper>
          <effort>60</effort>
          <velocity>6</velocity>
        </limit>
        <dynamics>
          <spring_reference>0</spring_reference>
          <spring_stiffness>0</spring_stiffness>
        </dynamics>
      </axis>
    </joint>
    <link name='back_left_lowerleg'>
      <pose relative_to='back_left_knee_joint'>0 0 0 0 -0 0</pose>
      <inertial>
        <pose>0 -0.028904 -0.143425 0 -0 0</pose>
        <mass>0.303</mass>
        <inertia>
          <ixx>0.00529148</ixx>
          <ixy>0</ixy>
          <ixz>0</ixz>
          <iyy>0.00511064</iyy>
          <iyz>-4.15933e-06</iyz>
          <izz>0.000800838</izz>
        </inertia>
      </inertial>
      <collision name='back_left_lowerleg_collision'>
        <pose>0 0 0 0 1.5708 0</pose>
        <geometry>
          <cylinder>
            <length>0.033</length>
            <radius>0.042</radius>
          </cylinder>
        </geometry>
        <surface>
          <contact>
            <ode>
              <kp>1e+06</kp>
              <kd>1</kd>
            </ode>
          </contact>
          <friction>
            <ode>
              <mu>2000</mu>
              <mu2>1000</mu2>
            </ode>
          </friction>
        </surface>
      </collision>
      <collision name='back_left_lowerleg_collision_1'>
        <pose>0.024 -0.0375 -0.0055 0 -0 0</pose>
        <geometry>
          <box>
            <size>0.02 0.017 0.065</size>
          </box>
        </geometry>
        <surface>
          <contact>
            <ode>
              <kp>1e+06</kp>
              <kd>1</kd>
            </ode>
          </contact>
          <friction>
            <ode>
              <mu>2000</mu>
              <mu2>1000</mu2>
            </ode>
          </friction>
        </surface>
      </collision>
      <collision name='back_left_lowerleg_collision_2'>
        <pose>-0.024 -0.0375 -0.0055 0 -0 0</pose>
        <geometry>
          <box>
            <size>0.02 0.017 0.065</size>
          </box>
        </geometry>
        <surface>
          <contact>
            <ode>
              <kp>1e+06</kp>
              <kd>1</kd>
            </ode>
          </contact>
          <friction>
            <ode>
              <mu>2000</mu>
              <mu2>1000</mu2>
            </ode>
          </friction>
        </surface>
      </collision>
      <collision name='back_left_lowerleg_collision_3'>
        <pose>0.01575 -0.0375 -0.145 0 0.04996 0</pose>
        <geometry>
          <cylinder>
            <length>0.29</length>
            <radius>0.006</radius>
          </cylinder>
        </geometry>
        <surface>
          <contact>
            <ode>
              <kp>1e+06</kp>
              <kd>1</kd>
            </ode>
          </contact>
          <friction>
            <ode>
              <mu>2000</mu>
              <mu2>1000</mu2>
            </ode>
          </friction>
        </surface>
      </collision>
      <collision name='back_left_lowerleg_collision_4'>
        <pose>-0.01575 -0.0375 -0.145 0 -0.04996 0</pose>
        <geometry>
          <cylinder>
            <length>0.29</length>
            <radius>0.006</radius>
          </cylinder>
        </geometry>
        <surface>
          <contact>
            <ode>
              <kp>1e+06</kp>
              <kd>1</kd>
            </ode>
          </contact>
          <friction>
            <ode>
              <mu>2000</mu>
              <mu2>1000</mu2>
            </ode>
          </friction>
        </surface>
      </collision>
      <collision name='back_left_lowerleg_fixed_joint_lump__back_left_foot_collision_5'>
        <pose>0 -0.035 -0.3 0 -0 0</pose>
        <geometry>
          <sphere>
            <radius>0.028</radius>
          </sphere>
        </geometry>
        <surface>
          <contact>
            <ode>
              <kp>1e+06</kp>
              <kd>1</kd>
            </ode>
          </contact>
          <friction>
            <ode>
              <mu>2000</mu>
              <mu2>1000</mu2>
            </ode>
          </friction>
        </surface>
      </collision>
      <visual name='back_left_lowerleg_visual'>
        <pose>0 0 0 -1.5708 0 0</pose>
        <geometry>
          <mesh>
            <scale>1 1 1</scale>
            <uri>model://dogbot_description/meshes/LegLower_nofoot.dae</uri>
          </mesh>
        </geometry>
      </visual>
      <visual name='back_left_lowerleg_fixed_joint_lump__back_left_foot_visual_1'>
        <pose>0 0 0 -1.5708 0 0</pose>
        <geometry>
          <mesh>
            <scale>1 1 1</scale>
            <uri>model://dogbot_description/meshes/foot.dae</uri>
          </mesh>
        </geometry>
      </visual>
      <self_collide>1</self_collide>
    </link>
    <joint name='back_right_roll_joint' type='revolute'>
      <pose relative_to='base'>0.28757 0.087771 0 0 -0 1.57</pose>
      <parent>base</parent>
      <child>back_right_hip</child>
      <axis>
        <xyz>0 -1 0</xyz>
        <limit>
          <lower>-1.7453</lower>
          <upper>1.7453</upper>
          <effort>60</effort>
          <velocity>6</velocity>
        </limit>
        <dynamics>
          <spring_reference>0</spring_reference>
          <spring_stiffness>0</spring_stiffness>
        </dynamics>
      </axis>
    </joint>
    <link name='back_right_hip'>
      <pose relative_to='back_right_roll_joint'>0 0 0 0 -0 0</pose>
      <inertial>
        <pose>0.0074 0 0 0 -0 0</pose>
        <mass>0.836</mass>
        <inertia>
          <ixx>0.00213</ixx>
          <ixy>0</ixy>
          <ixz>0</ixz>
          <iyy>0.00147</iyy>
          <iyz>0</iyz>
          <izz>0.00172</izz>
        </inertia>
      </inertial>
      <collision name='back_right_hip_collision'>
        <pose>0.02 0 0 0 1.5708 0</pose>
        <geometry>
          <cylinder>
            <length>0.08</length>
            <radius>0.0525</radius>
          </cylinder>
        </geometry>
      </collision>
      <visual name='back_right_hip_visual'>
        <pose>0 0 0 -1.5708 0 0</pose>
        <geometry>
          <mesh>
            <scale>1 1 1</scale>
            <uri>model://dogbot_description/meshes/hip.dae</uri>
          </mesh>
        </geometry>
      </visual>
    </link>
    <joint name='back_right_pitch_joint' type='revolute'>
      <pose relative_to='back_right_hip'>0.09875 0 0 0 -0 0</pose>
      <parent>back_right_hip</parent>
      <child>back_right_upperleg</child>
      <axis>
        <xyz>1 0 0</xyz>
        <limit>
          <lower>-3.14159</lower>
          <upper>1.5708</upper>
          <effort>60</effort>
          <velocity>6</velocity>
        </limit>
        <dynamics>
          <spring_reference>0</spring_reference>
          <spring_stiffness>0</spring_stiffness>
        </dynamics>
      </axis>
    </joint>
    <link name='back_right_upperleg'>
      <pose relative_to='back_right_pitch_joint'>0 0 0 0 -0 0</pose>
      <inertial>
        <pose>0.0418 0 -0.0517 0 -0 0</pose>
        <mass>1.851</mass>
        <inertia>
          <ixx>0.0238</ixx>
          <ixy>0</ixy>
          <ixz>0</ixz>
          <iyy>0.0252</iyy>
          <iyz>0</iyz>
          <izz>0.0044</izz>
        </inertia>
      </inertial>
      <collision name='back_right_upperleg_collision'>
        <pose>0.03 0 0 0 1.5708 0</pose>
        <geometry>
          <cylinder>
            <length>0.13</length>
            <radius>0.0525</radius>
          </cylinder>
        </geometry>
      </collision>
      <collision name='back_right_upperleg_collision_1'>
        <pose>0 0 -0.135 0 -0 0</pose>
        <geometry>
          <cylinder>
            <length>0.27</length>
            <radius>0.033</radius>
          </cylinder>
        </geometry>
      </collision>
      <collision name='back_right_upperleg_collision_2'>
        <pose>0 0 -0.135 0 -0 0</pose>
        <geometry>
          <box>
            <size>0.025 0.084 0.27</size>
          </box>
        </geometry>
      </collision>
      <collision name='back_right_upperleg_collision_3'>
        <pose>0.046 0 -0.126 0 -0 0</pose>
        <geometry>
          <box>
            <size>0.026 0.074 0.138</size>
          </box>
        </geometry>
      </collision>
      <collision name='back_right_upperleg_collision_4'>
        <pose>0.03 0 -0.315 0 1.5708 0</pose>
        <geometry>
          <cylinder>
            <length>0.018</length>
            <radius>0.017</radius>
          </cylinder>
        </geometry>
      </collision>
      <collision name='back_right_upperleg_collision_5'>
        <pose>-0.036 0 -0.315 0 1.5708 0</pose>
        <geometry>
          <cylinder>
            <length>0.013</length>
            <radius>0.017</radius>
          </cylinder>
        </geometry>
      </collision>
      <visual name='back_right_upperleg_visual'>
        <pose>0 0 0 -1.5708 0 0</pose>
        <geometry>
          <mesh>
            <scale>1 1 1</scale>
            <uri>model://dogbot_description/meshes/LegUpper_withCover.dae</uri>
          </mesh>
        </geometry>
      </visual>
    </link>
    <joint name='back_right_knee_joint' type='revolute'>
      <pose relative_to='back_right_upperleg'>0 0 -0.315 0 -0 0</pose>
      <parent>back_right_upperleg</parent>
      <child>back_right_lowerleg</child>
      <axis>
        <xyz>-1 0 0</xyz>
        <limit>
          <lower>-0.02</lower>
          <upper>2.61795</upper>
          <effort>60</effort>
          <velocity>6</velocity>
        </limit>
        <dynamics>
          <spring_reference>0</spring_reference>
          <spring_stiffness>0</spring_stiffness>
        </dynamics>
      </axis>
    </joint>
    <link name='back_right_lowerleg'>
      <pose relative_to='back_right_knee_joint'>0 0 0 0 -0 0</pose>
      <inertial>
        <pose>0 -0.028904 -0.143425 0 -0 0</pose>
        <mass>0.303</mass>
        <inertia>
          <ixx>0.00529148</ixx>
          <ixy>0</ixy>
          <ixz>0</ixz>
          <iyy>0.00511064</iyy>
          <iyz>-4.15933e-06</iyz>
          <izz>0.000800838</izz>
        </inertia>
      </inertial>
      <collision name='back_right_lowerleg_collision'>
        <pose>0 0 0 0 1.5708 0</pose>
        <geometry>
          <cylinder>
            <length>0.033</length>
            <radius>0.042</radius>
          </cylinder>
        </geometry>
        <surface>
          <contact>
            <ode>
              <kp>1e+06</kp>
              <kd>1</kd>
            </ode>
          </contact>
          <friction>
            <ode>
              <mu>2000</mu>
              <mu2>1000</mu2>
            </ode>
          </friction>
        </surface>
      </collision>
      <collision name='back_right_lowerleg_collision_1'>
        <pose>0.024 -0.0375 -0.0055 0 -0 0</pose>
        <geometry>
          <box>
            <size>0.02 0.017 0.065</size>
          </box>
        </geometry>
        <surface>
          <contact>
            <ode>
              <kp>1e+06</kp>
              <kd>1</kd>
            </ode>
          </contact>
          <friction>
            <ode>
              <mu>2000</mu>
              <mu2>1000</mu2>
            </ode>
          </friction>
        </surface>
      </collision>
      <collision name='back_right_lowerleg_collision_2'>
        <pose>-0.024 -0.0375 -0.0055 0 -0 0</pose>
        <geometry>
          <box>
            <size>0.02 0.017 0.065</size>
          </box>
        </geometry>
        <surface>
          <contact>
            <ode>
              <kp>1e+06</kp>
              <kd>1</kd>
            </ode>
          </contact>
          <friction>
            <ode>
              <mu>2000</mu>
              <mu2>1000</mu2>
            </ode>
          </friction>
        </surface>
      </collision>
      <collision name='back_right_lowerleg_collision_3'>
        <pose>0.01575 -0.0375 -0.145 0 0.04996 0</pose>
        <geometry>
          <cylinder>
            <length>0.29</length>
            <radius>0.006</radius>
          </cylinder>
        </geometry>
        <surface>
          <contact>
            <ode>
              <kp>1e+06</kp>
              <kd>1</kd>
            </ode>
          </contact>
          <friction>
            <ode>
              <mu>2000</mu>
              <mu2>1000</mu2>
            </ode>
          </friction>
        </surface>
      </collision>
      <collision name='back_right_lowerleg_collision_4'>
        <pose>-0.01575 -0.0375 -0.145 0 -0.04996 0</pose>
        <geometry>
          <cylinder>
            <length>0.29</length>
            <radius>0.006</radius>
          </cylinder>
        </geometry>
        <surface>
          <contact>
            <ode>
              <kp>1e+06</kp>
              <kd>1</kd>
            </ode>
          </contact>
          <friction>
            <ode>
              <mu>2000</mu>
              <mu2>1000</mu2>
            </ode>
          </friction>
        </surface>
      </collision>
      <collision name='back_right_lowerleg_fixed_joint_lump__back_right_foot_collision_5'>
        <pose>0 -0.035 -0.3 0 -0 0</pose>
        <geometry>
          <sphere>
            <radius>0.028</radius>
          </sphere>
        </geometry>
        <surface>
          <contact>
            <ode>
              <kp>1e+06</kp>
              <kd>1</kd>
            </ode>
          </contact>
          <friction>
            <ode>
              <mu>2000</mu>
              <mu2>1000</mu2>
            </ode>
          </friction>
        </surface>
      </collision>
      <visual name='back_right_lowerleg_visual'>
        <pose>0 0 0 -1.5708 0 0</pose>
        <geometry>
          <mesh>
            <scale>1 1 1</scale>
            <uri>model://dogbot_description/meshes/LegLower_nofoot.dae</uri>
          </mesh>
        </geometry>
      </visual>
      <visual name='back_right_lowerleg_fixed_joint_lump__back_right_foot_visual_1'>
        <pose>0 0 0 -1.5708 0 0</pose>
        <geometry>
          <mesh>
            <scale>1 1 1</scale>
            <uri>model://dogbot_description/meshes/foot.dae</uri>
          </mesh>
        </geometry>
      </visual>
      <self_collide>1</self_collide>
    </link>
    <joint name='front_left_roll_joint' type='revolute'>
      <pose relative_to='base'>-0.28757 -0.087771 0 0 -0 1.57</pose>
      <parent>base</parent>
      <child>front_left_hip</child>
      <axis>
        <xyz>0 1 0</xyz>
        <limit>
          <lower>-1.7453</lower>
          <upper>1.7453</upper>
          <effort>60</effort>
          <velocity>6</velocity>
        </limit>
        <dynamics>
          <spring_reference>0</spring_reference>
          <spring_stiffness>0</spring_stiffness>
        </dynamics>
      </axis>
    </joint>
    <link name='front_left_hip'>
      <pose relative_to='front_left_roll_joint'>0 0 0 0 -0 0</pose>
      <inertial>
        <pose>-0.0074 0 0 0 -0 0</pose>
        <mass>0.836</mass>
        <inertia>
          <ixx>0.00213</ixx>
          <ixy>0</ixy>
          <ixz>0</ixz>
          <iyy>0.00147</iyy>
          <iyz>0</iyz>
          <izz>0.00172</izz>
        </inertia>
      </inertial>
      <collision name='front_left_hip_collision'>
        <pose>-0.02 0 0 0 1.5708 0</pose>
        <geometry>
          <cylinder>
            <length>0.08</length>
            <radius>0.0525</radius>
          </cylinder>
        </geometry>
      </collision>
      <visual name='front_left_hip_visual'>
        <pose>0 0 0 1.5708 0 -3.14159</pose>
        <geometry>
          <mesh>
            <scale>1 1 1</scale>
            <uri>model://dogbot_description/meshes/hip.dae</uri>
          </mesh>
        </geometry>
      </visual>
    </link>
    <joint name='front_left_pitch_joint' type='revolute'>
      <pose relative_to='front_left_hip'>-0.09875 0 0 0 -0 0</pose>
      <parent>front_left_hip</parent>
      <child>front_left_upperleg</child>
      <axis>
        <xyz>-1 0 0</xyz>
        <limit>
          <lower>-1.5708</lower>
          <upper>3.14159</upper>
          <effort>60</effort>
          <velocity>6</velocity>
        </limit>
        <dynamics>
          <spring_reference>0</spring_reference>
          <spring_stiffness>0</spring_stiffness>
        </dynamics>
      </axis>
    </joint>
    <link name='front_left_upperleg'>
      <pose relative_to='front_left_pitch_joint'>0 0 0 0 -0 0</pose>
      <inertial>
        <pose>-0.0418 0 -0.0517 0 -0 0</pose>
        <mass>1.851</mass>
        <inertia>
          <ixx>0.0238</ixx>
          <ixy>0</ixy>
          <ixz>0</ixz>
          <iyy>0.0252</iyy>
          <iyz>0</iyz>
          <izz>0.0044</izz>
        </inertia>
      </inertial>
      <collision name='front_left_upperleg_collision'>
        <pose>-0.03 0 0 0 1.5708 0</pose>
        <geometry>
          <cylinder>
            <length>0.13</length>
            <radius>0.0525</radius>
          </cylinder>
        </geometry>
      </collision>
      <collision name='front_left_upperleg_collision_1'>
        <pose>0 0 -0.135 0 -0 0</pose>
        <geometry>
          <cylinder>
            <length>0.27</length>
            <radius>0.033</radius>
          </cylinder>
        </geometry>
      </collision>
      <collision name='front_left_upperleg_collision_2'>
        <pose>0 0 -0.135 0 -0 0</pose>
        <geometry>
          <box>
            <size>0.025 0.084 0.27</size>
          </box>
        </geometry>
      </collision>
      <collision name='front_left_upperleg_collision_3'>
        <pose>-0.046 0 -0.126 0 -0 0</pose>
        <geometry>
          <box>
            <size>0.026 0.074 0.138</size>
          </box>
        </geometry>
      </collision>
      <collision name='front_left_upperleg_collision_4'>
        <pose>-0.03 0 -0.315 0 1.5708 0</pose>
        <geometry>
          <cylinder>
            <length>0.018</length>
            <radius>0.017</radius>
          </cylinder>
        </geometry>
      </collision>
      <collision name='front_left_upperleg_collision_5'>
        <pose>0.036 0 -0.315 0 1.5708 0</pose>
        <geometry>
          <cylinder>
            <length>0.013</length>
            <radius>0.017</radius>
          </cylinder>
        </geometry>
      </collision>
      <visual name='front_left_upperleg_visual'>
        <pose>0 0 0 -1.5708 -0 3.14159</pose>
        <geometry>
          <mesh>
            <scale>1 1 1</scale>
            <uri>model://dogbot_description/meshes/LegUpper_withCover.dae</uri>
          </mesh>
        </geometry>
      </visual>
    </link>
    <joint name='front_left_knee_joint' type='revolute'>
      <pose relative_to='front_left_upperleg'>0 0 -0.315 0 -0 0</pose>
      <parent>front_left_upperleg</parent>
      <child>front_left_lowerleg</child>
      <axis>
        <xyz>1 0 0</xyz>
        <limit>
          <lower>-2.61795</lower>
          <upper>0.02</upper>
          <effort>60</effort>
          <velocity>6</velocity>
        </limit>
        <dynamics>
          <spring_reference>0</spring_reference>
          <spring_stiffness>0</spring_stiffness>
        </dynamics>
      </axis>
    </joint>
    <link name='front_left_lowerleg'>
      <pose relative_to='front_left_knee_joint'>0 0 0 0 -0 0</pose>
      <inertial>
        <pose>0 -0.028904 -0.143425 0 -0 0</pose>
        <mass>0.303</mass>
        <inertia>
          <ixx>0.00529148</ixx>
          <ixy>0</ixy>
          <ixz>0</ixz>
          <iyy>0.00511064</iyy>
          <iyz>-4.15933e-06</iyz>
          <izz>0.000800838</izz>
        </inertia>
      </inertial>
      <collision name='front_left_lowerleg_collision'>
        <pose>0 0 0 0 1.5708 0</pose>
        <geometry>
          <cylinder>
            <length>0.033</length>
            <radius>0.042</radius>
          </cylinder>
        </geometry>
        <surface>
          <contact>
            <ode>
              <kp>1e+06</kp>
              <kd>1</kd>
            </ode>
          </contact>
          <friction>
            <ode>
              <mu>2000</mu>
              <mu2>1000</mu2>
            </ode>
          </friction>
        </surface>
      </collision>
      <collision name='front_left_lowerleg_collision_1'>
        <pose>0.024 -0.0375 -0.0055 0 -0 0</pose>
        <geometry>
          <box>
            <size>0.02 0.017 0.065</size>
          </box>
        </geometry>
        <surface>
          <contact>
            <ode>
              <kp>1e+06</kp>
              <kd>1</kd>
            </ode>
          </contact>
          <friction>
            <ode>
              <mu>2000</mu>
              <mu2>1000</mu2>
            </ode>
          </friction>
        </surface>
      </collision>
      <collision name='front_left_lowerleg_collision_2'>
        <pose>-0.024 -0.0375 -0.0055 0 -0 0</pose>
        <geometry>
          <box>
            <size>0.02 0.017 0.065</size>
          </box>
        </geometry>
        <surface>
          <contact>
            <ode>
              <kp>1e+06</kp>
              <kd>1</kd>
            </ode>
          </contact>
          <friction>
            <ode>
              <mu>2000</mu>
              <mu2>1000</mu2>
            </ode>
          </friction>
        </surface>
      </collision>
      <collision name='front_left_lowerleg_collision_3'>
        <pose>0.01575 -0.0375 -0.145 0 0.04996 0</pose>
        <geometry>
          <cylinder>
            <length>0.29</length>
            <radius>0.006</radius>
          </cylinder>
        </geometry>
        <surface>
          <contact>
            <ode>
              <kp>1e+06</kp>
              <kd>1</kd>
            </ode>
          </contact>
          <friction>
            <ode>
              <mu>2000</mu>
              <mu2>1000</mu2>
            </ode>
          </friction>
        </surface>
      </collision>
      <collision name='front_left_lowerleg_collision_4'>
        <pose>-0.01575 -0.0375 -0.145 0 -0.04996 0</pose>
        <geometry>
          <cylinder>
            <length>0.29</length>
            <radius>0.006</radius>
          </cylinder>
        </geometry>
        <surface>
          <contact>
            <ode>
              <kp>1e+06</kp>
              <kd>1</kd>
            </ode>
          </contact>
          <friction>
            <ode>
              <mu>2000</mu>
              <mu2>1000</mu2>
            </ode>
          </friction>
        </surface>
      </collision>
      <collision name='front_left_lowerleg_fixed_joint_lump__front_left_foot_collision_5'>
        <pose>0 -0.035 -0.3 0 -0 0</pose>
        <geometry>
          <sphere>
            <radius>0.028</radius>
          </sphere>
        </geometry>
        <surface>
          <contact>
            <ode>
              <kp>1e+06</kp>
              <kd>1</kd>
            </ode>
          </contact>
          <friction>
            <ode>
              <mu>2000</mu>
              <mu2>1000</mu2>
            </ode>
          </friction>
        </surface>
      </collision>
      <visual name='front_left_lowerleg_visual'>
        <pose>0 0 0 -1.5708 0 0</pose>
        <geometry>
          <mesh>
            <scale>1 1 1</scale>
            <uri>model://dogbot_description/meshes/LegLower_nofoot.dae</uri>
          </mesh>
        </geometry>
      </visual>
      <visual name='front_left_lowerleg_fixed_joint_lump__front_left_foot_visual_1'>
        <pose>0 0 0 -1.5708 0 0</pose>
        <geometry>
          <mesh>
            <scale>1 1 1</scale>
            <uri>model://dogbot_description/meshes/foot.dae</uri>
          </mesh>
        </geometry>
      </visual>
      <self_collide>1</self_collide>
    </link>
    <joint name='front_right_roll_joint' type='revolute'>
      <pose relative_to='base'>-0.28743 0.088229 0 0 -0 1.57</pose>
      <parent>base</parent>
      <child>front_right_hip</child>
      <axis>
        <xyz>0 1 0</xyz>
        <limit>
          <lower>-1.7453</lower>
          <upper>1.7453</upper>
          <effort>60</effort>
          <velocity>6</velocity>
        </limit>
        <dynamics>
          <spring_reference>0</spring_reference>
          <spring_stiffness>0</spring_stiffness>
        </dynamics>
      </axis>
    </joint>
    <link name='front_right_hip'>
      <pose relative_to='front_right_roll_joint'>0 0 0 0 -0 0</pose>
      <inertial>
        <pose>0.0074 0 0 0 -0 0</pose>
        <mass>0.836</mass>
        <inertia>
          <ixx>0.00213</ixx>
          <ixy>0</ixy>
          <ixz>0</ixz>
          <iyy>0.00147</iyy>
          <iyz>0</iyz>
          <izz>0.00172</izz>
        </inertia>
      </inertial>
      <collision name='front_right_hip_collision'>
        <pose>0.02 0 0 0 1.5708 0</pose>
        <geometry>
          <cylinder>
            <length>0.08</length>
            <radius>0.0525</radius>
          </cylinder>
        </geometry>
      </collision>
      <visual name='front_right_hip_visual'>
        <pose>0 0 0 -1.5708 0 0</pose>
        <geometry>
          <mesh>
            <scale>1 1 1</scale>
            <uri>model://dogbot_description/meshes/hip.dae</uri>
          </mesh>
        </geometry>
      </visual>
    </link>
    <joint name='front_right_pitch_joint' type='revolute'>
      <pose relative_to='front_right_hip'>0.09875 0 0 0 -0 0</pose>
      <parent>front_right_hip</parent>
      <child>front_right_upperleg</child>
      <axis>
        <xyz>1 0 0</xyz>
        <limit>
          <lower>-3.14159</lower>
          <upper>1.5708</upper>
          <effort>60</effort>
          <velocity>6</velocity>
        </limit>
        <dynamics>
          <spring_reference>0</spring_reference>
          <spring_stiffness>0</spring_stiffness>
        </dynamics>
      </axis>
    </joint>
    <link name='front_right_upperleg'>
      <pose relative_to='front_right_pitch_joint'>0 0 0 0 -0 0</pose>
      <inertial>
        <pose>0.0418 0 -0.0517 0 -0 0</pose>
        <mass>1.851</mass>
        <inertia>
          <ixx>0.0238</ixx>
          <ixy>0</ixy>
          <ixz>0</ixz>
          <iyy>0.0252</iyy>
          <iyz>0</iyz>
          <izz>0.0044</izz>
        </inertia>
      </inertial>
      <collision name='front_right_upperleg_collision'>
        <pose>0.03 0 0 0 1.5708 0</pose>
        <geometry>
          <cylinder>
            <length>0.13</length>
            <radius>0.0525</radius>
          </cylinder>
        </geometry>
      </collision>
      <collision name='front_right_upperleg_collision_1'>
        <pose>0 0 -0.135 0 -0 0</pose>
        <geometry>
          <cylinder>
            <length>0.27</length>
            <radius>0.033</radius>
          </cylinder>
        </geometry>
      </collision>
      <collision name='front_right_upperleg_collision_2'>
        <pose>0 0 -0.135 0 -0 0</pose>
        <geometry>
          <box>
            <size>0.025 0.084 0.27</size>
          </box>
        </geometry>
      </collision>
      <collision name='front_right_upperleg_collision_3'>
        <pose>0.046 0 -0.126 0 -0 0</pose>
        <geometry>
          <box>
            <size>0.026 0.074 0.138</size>
          </box>
        </geometry>
      </collision>
      <collision name='front_right_upperleg_collision_4'>
        <pose>0.03 0 -0.315 0 1.5708 0</pose>
        <geometry>
          <cylinder>
            <length>0.018</length>
            <radius>0.017</radius>
          </cylinder>
        </geometry>
      </collision>
      <collision name='front_right_upperleg_collision_5'>
        <pose>-0.036 0 -0.315 0 1.5708 0</pose>
        <geometry>
          <cylinder>
            <length>0.013</length>
            <radius>0.017</radius>
          </cylinder>
        </geometry>
      </collision>
      <visual name='front_right_upperleg_visual'>
        <pose>0 0 0 -1.5708 0 0</pose>
        <geometry>
          <mesh>
            <scale>1 1 1</scale>
            <uri>model://dogbot_description/meshes/LegUpper_withCover.dae</uri>
          </mesh>
        </geometry>
      </visual>
    </link>
    <joint name='front_right_knee_joint' type='revolute'>
      <pose relative_to='front_right_upperleg'>0 0 -0.315 0 -0 0</pose>
      <parent>front_right_upperleg</parent>
      <child>front_right_lowerleg</child>
      <axis>
        <xyz>-1 0 0</xyz>
        <limit>
          <lower>-0.02</lower>
          <upper>2.61795</upper>
          <effort>60</effort>
          <velocity>6</velocity>
        </limit>
        <dynamics>
          <spring_reference>0</spring_reference>
          <spring_stiffness>0</spring_stiffness>
        </dynamics>
      </axis>
    </joint>
    <link name='front_right_lowerleg'>
      <pose relative_to='front_right_knee_joint'>0 0 0 0 -0 0</pose>
      <inertial>
        <pose>0 -0.028904 -0.143425 0 -0 0</pose>
        <mass>0.303</mass>
        <inertia>
          <ixx>0.00529148</ixx>
          <ixy>0</ixy>
          <ixz>0</ixz>
          <iyy>0.00511064</iyy>
          <iyz>-4.15933e-06</iyz>
          <izz>0.000800838</izz>
        </inertia>
      </inertial>
      <collision name='front_right_lowerleg_collision'>
        <pose>0 0 0 0 1.5708 0</pose>
        <geometry>
          <cylinder>
            <length>0.033</length>
            <radius>0.042</radius>
          </cylinder>
        </geometry>
        <surface>
          <contact>
            <ode>
              <kp>1e+06</kp>
              <kd>1</kd>
            </ode>
          </contact>
          <friction>
            <ode>
              <mu>2000</mu>
              <mu2>1000</mu2>
            </ode>
          </friction>
        </surface>
      </collision>
      <collision name='front_right_lowerleg_collision_1'>
        <pose>0.024 -0.0375 -0.0055 0 -0 0</pose>
        <geometry>
          <box>
            <size>0.02 0.017 0.065</size>
          </box>
        </geometry>
        <surface>
          <contact>
            <ode>
              <kp>1e+06</kp>
              <kd>1</kd>
            </ode>
          </contact>
          <friction>
            <ode>
              <mu>2000</mu>
              <mu2>1000</mu2>
            </ode>
          </friction>
        </surface>
      </collision>
      <collision name='front_right_lowerleg_collision_2'>
        <pose>-0.024 -0.0375 -0.0055 0 -0 0</pose>
        <geometry>
          <box>
            <size>0.02 0.017 0.065</size>
          </box>
        </geometry>
        <surface>
          <contact>
            <ode>
              <kp>1e+06</kp>
              <kd>1</kd>
            </ode>
          </contact>
          <friction>
            <ode>
              <mu>2000</mu>
              <mu2>1000</mu2>
            </ode>
          </friction>
        </surface>
      </collision>
      <collision name='front_right_lowerleg_collision_3'>
        <pose>0.01575 -0.0375 -0.145 0 0.04996 0</pose>
        <geometry>
          <cylinder>
            <length>0.29</length>
            <radius>0.006</radius>
          </cylinder>
        </geometry>
        <surface>
          <contact>
            <ode>
              <kp>1e+06</kp>
              <kd>1</kd>
            </ode>
          </contact>
          <friction>
            <ode>
              <mu>2000</mu>
              <mu2>1000</mu2>
            </ode>
          </friction>
        </surface>
      </collision>
      <collision name='front_right_lowerleg_collision_4'>
        <pose>-0.01575 -0.0375 -0.145 0 -0.04996 0</pose>
        <geometry>
          <cylinder>
            <length>0.29</length>
            <radius>0.006</radius>
          </cylinder>
        </geometry>
        <surface>
          <contact>
            <ode>
              <kp>1e+06</kp>
              <kd>1</kd>
            </ode>
          </contact>
          <friction>
            <ode>
              <mu>2000</mu>
              <mu2>1000</mu2>
            </ode>
          </friction>
        </surface>
      </collision>
      <collision name='front_right_lowerleg_fixed_joint_lump__front_right_foot_collision_5'>
        <pose>0 -0.035 -0.3 0 -0 0</pose>
        <geometry>
          <sphere>
            <radius>0.028</radius>
          </sphere>
        </geometry>
        <surface>
          <contact>
            <ode>
              <kp>1e+06</kp>
              <kd>1</kd>
            </ode>
          </contact>
          <friction>
            <ode>
              <mu>2000</mu>
              <mu2>1000</mu2>
            </ode>
          </friction>
        </surface>
      </collision>
      <visual name='front_right_lowerleg_visual'>
        <pose>0 0 0 -1.5708 0 0</pose>
        <geometry>
          <mesh>
            <scale>1 1 1</scale>
            <uri>model://dogbot_description/meshes/LegLower_nofoot.dae</uri>
          </mesh>
        </geometry>
      </visual>
      <visual name='front_right_lowerleg_fixed_joint_lump__front_right_foot_visual_1'>
        <pose>0 0 0 -1.5708 0 0</pose>
        <geometry>
          <mesh>
            <scale>1 1 1</scale>
            <uri>model://dogbot_description/meshes/foot.dae</uri>
          </mesh>
        </geometry>
      </visual>
      <self_collide>1</self_collide>
    </link>
    <plugin name='camera' filename='librealsense_gazebo_plugin.so'>
      <prefix>camera</prefix>
      <depthUpdateRate>30.0</depthUpdateRate>
      <colorUpdateRate>30.0</colorUpdateRate>
      <infraredUpdateRate>30.0</infraredUpdateRate>
      <depthTopicName>depth/image_raw</depthTopicName>
      <depthCameraInfoTopicName>depth/camera_info</depthCameraInfoTopicName>
      <colorTopicName>color/image_raw</colorTopicName>
      <colorCameraInfoTopicName>color/camera_info</colorCameraInfoTopicName>
      <infrared1TopicName>infra1/image_raw</infrared1TopicName>
      <infrared1CameraInfoTopicName>infra1/camera_info</infrared1CameraInfoTopicName>
      <infrared2TopicName>infra2/image_raw</infrared2TopicName>
      <infrared2CameraInfoTopicName>infra2/camera_info</infrared2CameraInfoTopicName>
      <colorOpticalframeName>camera_depth_optical_frame</colorOpticalframeName>
      <depthOpticalframeName>camera_depth_optical_frame</depthOpticalframeName>
      <infrared1OpticalframeName>camera_left_ir_optical_frame</infrared1OpticalframeName>
      <infrared2OpticalframeName>camera_right_ir_optical_frame</infrared2OpticalframeName>
      <rangeMinDepth>0.28</rangeMinDepth>
      <rangeMaxDepth>10.0</rangeMaxDepth>
    </plugin>
    <plugin name='imu_plugin' filename='libhector_gazebo_ros_imu.so'>
      <alwaysOn>1</alwaysOn>
      <robotNamespace>dogbot</robotNamespace>
      <topicName>imu</topicName>
      <serviceName>imu_service</serviceName>
      <gaussianNoise>0.0</gaussianNoise>
      <updateRate>20.0</updateRate>
      <bodyName>base</bodyName>
      <xyzOffset>0 0 0</xyzOffset>
      <rpyOffset>0 -0 1.57</rpyOffset>
      <ignition::corrected_offsets>1</ignition::corrected_offsets>
    </plugin>
    <plugin name='gps_plugin' filename='libhector_gazebo_ros_gps.so'>
      <alwaysOn>1</alwaysOn>
      <robotNamespace>dogbot</robotNamespace>
      <topicName>gps</topicName>
      <serviceName>imu_service</serviceName>
      <updateRate>100</updateRate>
      <referenceLatitude>51.5</referenceLatitude>
      <referenceLongitude>0.1278</referenceLongitude>
      <bodyName>base</bodyName>
      <xyzOffset>0 0 0</xyzOffset>
      <rpyOffset>0 -0 1.57</rpyOffset>
      <ignition::corrected_offsets>1</ignition::corrected_offsets>
    </plugin>
    <static>0</static>
    <plugin name='gazebo_ros_control' filename='libgazebo_ros_control.so'>
      <robotNamespace>/dogbot</robotNamespace>
    </plugin>
  </model>
</sdf>
